Workbook

Sheet Public Tool
A1: TAPIR Public Decision-Support Tool | B1: TAPIR Public Decision-Support Tool | C1: TAPIR Public Decision-Support Tool | D1: TAPIR Public Decision-Support Tool | E1: TAPIR Public Decision-Support Tool | F1: TAPIR Public Decision-Support Tool | G1: TAPIR Public Decision-Support Tool | H1: TAPIR Public Decision-Support Tool | I1: TAPIR Public Decision-Support Tool | J1: TAPIR Public Decision-Support Tool | K1: TAPIR Public Decision-Support Tool | L1: TAPIR Public Decision-Support Tool
A2: Compare the same four response options using anonymised case evidence and percentage-only load indicators | B2: Compare the same four response options using anonymised case evidence and percentage-only load indicators | C2: Compare the same four response options using anonymised case evidence and percentage-only load indicators | D2: Compare the same four response options using anonymised case evidence and percentage-only load indicators | E2: Compare the same four response options using anonymised case evidence and percentage-only load indicators | F2: Compare the same four response options using anonymised case evidence and percentage-only load indicators | G2: Compare the same four response options using anonymised case evidence and percentage-only load indicators | H2: Compare the same four response options using anonymised case evidence and percentage-only load indicators | I2: Compare the same four response options using anonymised case evidence and percentage-only load indicators | J2: Compare the same four response options using anonymised case evidence and percentage-only load indicators | K2: Compare the same four response options using anonymised case evidence and percentage-only load indicators | L2: Compare the same four response options using anonymised case evidence and percentage-only load indicators
A3: SELECTED CASE | B3: SELECTED CASE | C3: Schouwen-Duiveland | D3: Schouwen-Duiveland | E3: Schouwen-Duiveland | F3: Schouwen-Duiveland | G3: Schouwen-Duiveland | H3: Schouwen-Duiveland | I3: Schouwen-Duiveland | J3: Schouwen-Duiveland | K3: Schouwen-Duiveland | L3: Schouwen-Duiveland
A4: Response-option ranking | B4: Response-option ranking | C4: Response-option ranking | D4: Response-option ranking | E4: Response-option ranking | F4: Response-option ranking | H4: Preferred response option | I4: Preferred response option | J4: Preferred response option | K4: Preferred response option | L4: Preferred response option
A5: Response option | D5: Grid operator | E5: Company | F5: Equal actor average | H5: =INDEX($A$6:$A$9,MATCH(MAX($F$6:$F$9),$F$6:$F$9,0)) -> Battery + EMS
A6: Conventional grid reinforcement | D6: =SUMIFS('Public Inputs'!$P$6:$P$17,'Public Inputs'!$N$6:$N$17,$C$3,'Public Inputs'!$O$6:$O$17,$A6) -> 2.85 | E6: =SUMIFS('Public Inputs'!$Q$6:$Q$17,'Public Inputs'!$N$6:$N$17,$C$3,'Public Inputs'!$O$6:$O$17,$A6) -> 2.5 | F6: =SUMIFS('Public Inputs'!$R$6:$R$17,'Public Inputs'!$N$6:$N$17,$C$3,'Public Inputs'!$O$6:$O$17,$A6) -> 2.675
A7: Battery + EMS | D7: =SUMIFS('Public Inputs'!$P$6:$P$17,'Public Inputs'!$N$6:$N$17,$C$3,'Public Inputs'!$O$6:$O$17,$A7) -> 3.65 | E7: =SUMIFS('Public Inputs'!$Q$6:$Q$17,'Public Inputs'!$N$6:$N$17,$C$3,'Public Inputs'!$O$6:$O$17,$A7) -> 4.25 | F7: =SUMIFS('Public Inputs'!$R$6:$R$17,'Public Inputs'!$N$6:$N$17,$C$3,'Public Inputs'!$O$6:$O$17,$A7) -> 3.95 | H7: ="Grid operator "&TEXT(INDEX($D$6:$D$9,MATCH($H$5,$A$6:$A$9,0)),"0.00")&" / 5 | Company "&TEXT(INDEX($E$6:$E$9,MATCH($H$5,$A$6:$A$9,0)),"0.00")&" / 5 | Overall "&TEXT(INDEX($F$6:$F$9,MATCH($H$5,$A$6:$A$9,0)),"0.00")&" / 5" -> Grid operator 004 / 5 | Company 004 / 5 | Overall 004 / 5
A8: Group Transport Agreement | D8: =SUMIFS('Public Inputs'!$P$6:$P$17,'Public Inputs'!$N$6:$N$17,$C$3,'Public Inputs'!$O$6:$O$17,$A8) -> 3.075 | E8: =SUMIFS('Public Inputs'!$Q$6:$Q$17,'Public Inputs'!$N$6:$N$17,$C$3,'Public Inputs'!$O$6:$O$17,$A8) -> 3.425 | F8: =SUMIFS('Public Inputs'!$R$6:$R$17,'Public Inputs'!$N$6:$N$17,$C$3,'Public Inputs'!$O$6:$O$17,$A8) -> 3.25 | H8: =INDEX('Public Inputs'!$K$22:$K$24,MATCH($C$3,'Public Inputs'!$A$22:$A$24,0)) -> The main distribution station is forecast to exceed the threshold before planned reinforcement. Both flexibility solutions reduce stress, but neither removes the exceedance; reinforcement therefore remains necessary.
A9: No additional intervention | D9: =SUMIFS('Public Inputs'!$P$6:$P$17,'Public Inputs'!$N$6:$N$17,$C$3,'Public Inputs'!$O$6:$O$17,$A9) -> 3.05 | E9: =SUMIFS('Public Inputs'!$Q$6:$Q$17,'Public Inputs'!$N$6:$N$17,$C$3,'Public Inputs'!$O$6:$O$17,$A9) -> 2.7 | F9: =SUMIFS('Public Inputs'!$R$6:$R$17,'Public Inputs'!$N$6:$N$17,$C$3,'Public Inputs'!$O$6:$O$17,$A9) -> 2.875
A11: Public case context | B11: Public case context | C11: Public case context | D11: Public case context | E11: Public case context | F11: Public case context | G11: Public case context | H11: Public case context | I11: Public case context | J11: Public case context | K11: Public case context | L11: Public case context
A12: Case region | E12: Village | I12: Evidence basis
A13: =$C$3 -> Schouwen-Duiveland | E13: =INDEX('Public Inputs'!$B$22:$B$24,MATCH($C$3,'Public Inputs'!$A$22:$A$24,0)) -> Village 1 | I13: =INDEX('Public Inputs'!$I$22:$I$24,MATCH($C$3,'Public Inputs'!$A$22:$A$24,0)) -> Forecast percentage
A14: Peak-period daily demand index | E14: Medium-voltage station ATC | G14: Main distribution station baseline ATC | I14: Public-data status
A15: =INDEX('Public Inputs'!$D$22:$D$24,MATCH($C$3,'Public Inputs'!$A$22:$A$24,0)) -> 0 | E15: =INDEX('Public Inputs'!$E$22:$E$24,MATCH($C$3,'Public Inputs'!$A$22:$A$24,0)) -> 0.887 | G15: =INDEX('Public Inputs'!$F$22:$F$24,MATCH($C$3,'Public Inputs'!$A$22:$A$24,0)) -> 0.97 | I15: Percentage-only indicators; identifiers and absolute values removed
A17: Percentage-based grid assessment | B17: Percentage-based grid assessment | C17: Percentage-based grid assessment | D17: Percentage-based grid assessment | E17: Percentage-based grid assessment | F17: Percentage-based grid assessment | G17: Percentage-based grid assessment | H17: Percentage-based grid assessment | I17: Percentage-based grid assessment | J17: Percentage-based grid assessment | K17: Percentage-based grid assessment | L17: Percentage-based grid assessment
A18: ATC indicators show load as a percentage of available transport capacity. The assessment threshold is 90%; no absolute load or capacity value is stored in this workbook.
A19: Assessment threshold | D19: Baseline ATC | G19: After battery + EMS | J19: After Group Transport Agreement
A20: 0.9 | D20: =INDEX('Public Inputs'!$F$22:$F$24,MATCH($C$3,'Public Inputs'!$A$22:$A$24,0)) -> 0.97 | G20: =INDEX('Public Inputs'!$G$22:$G$24,MATCH($C$3,'Public Inputs'!$A$22:$A$24,0)) -> 0.914 | J20: =INDEX('Public Inputs'!$H$22:$H$24,MATCH($C$3,'Public Inputs'!$A$22:$A$24,0)) -> 0.916
A21: Outcome | C21: =INDEX('Public Inputs'!$J$22:$J$24,MATCH($C$3,'Public Inputs'!$A$22:$A$24,0)) -> Neither flexibility solution clears the 90% threshold
A23: TAPIR-adjusted criteria and selected-case scores | B23: TAPIR-adjusted criteria and selected-case scores | C23: TAPIR-adjusted criteria and selected-case scores | D23: TAPIR-adjusted criteria and selected-case scores | E23: TAPIR-adjusted criteria and selected-case scores | F23: TAPIR-adjusted criteria and selected-case scores | G23: TAPIR-adjusted criteria and selected-case scores | H23: TAPIR-adjusted criteria and selected-case scores | I23: TAPIR-adjusted criteria and selected-case scores | J23: TAPIR-adjusted criteria and selected-case scores | K23: TAPIR-adjusted criteria and selected-case scores | L23: TAPIR-adjusted criteria and selected-case scores
A24: Actor | B24: Criterion | D24: Weight | E24: TAPIR factor | F24: Conventional grid reinforcement | G24: Battery + EMS | H24: Group Transport Agreement | I24: No additional intervention | J24: Case-specific public evidence
A25: Grid operator | B25: Grid-operator life-cycle cost and investment effect | D25: =INDEX('Public Inputs'!$C$6:$C$15,MATCH($B25,'Public Inputs'!$B$6:$B$15,0)) -> 0.3 | E25: =INDEX('Public Inputs'!$D$6:$D$15,MATCH($B25,'Public Inputs'!$B$6:$B$15,0)) -> Economic prospects | F25: =SUMIFS('Public Inputs'!$K$28:$K$147,'Public Inputs'!$A$28:$A$147,$C$3,'Public Inputs'!$B$28:$B$147,$A25,'Public Inputs'!$C$28:$C$147,$B25,'Public Inputs'!$D$28:$D$147,F$24) -> 2 | G25: =SUMIFS('Public Inputs'!$K$28:$K$147,'Public Inputs'!$A$28:$A$147,$C$3,'Public Inputs'!$B$28:$B$147,$A25,'Public Inputs'!$C$28:$C$147,$B25,'Public Inputs'!$D$28:$D$147,G$24) -> 4 | H25: =SUMIFS('Public Inputs'!$K$28:$K$147,'Public Inputs'!$A$28:$A$147,$C$3,'Public Inputs'!$B$28:$B$147,$A25,'Public Inputs'!$C$28:$C$147,$B25,'Public Inputs'!$D$28:$D$147,H$24) -> 4 | I25: =SUMIFS('Public Inputs'!$K$28:$K$147,'Public Inputs'!$A$28:$A$147,$C$3,'Public Inputs'!$B$28:$B$147,$A25,'Public Inputs'!$C$28:$C$147,$B25,'Public Inputs'!$D$28:$D$147,I$24) -> 5 | J25: =IF($C$3="Schouwen-Duiveland",INDEX('Public Inputs'!$P$22:$P$31,MATCH($B25,'Public Inputs'!$O$22:$O$31,0)),IF($C$3="Walcheren",INDEX('Public Inputs'!$P$32:$P$41,MATCH($B25,'Public Inputs'!$O$32:$O$41,0)),INDEX('Public Inputs'!$P$42:$P$51,MATCH($B25,'Public Inputs'!$O$42:$O$51,0)))) -> Base score unchanged for this criterion.
A26: Grid operator | B26: Timing, duration, reliability and predictability | D26: =INDEX('Public Inputs'!$C$6:$C$15,MATCH($B26,'Public Inputs'!$B$6:$B$15,0)) -> 0.2 | E26: =INDEX('Public Inputs'!$D$6:$D$15,MATCH($B26,'Public Inputs'!$B$6:$B$15,0)) -> Maturity | F26: =SUMIFS('Public Inputs'!$K$28:$K$147,'Public Inputs'!$A$28:$A$147,$C$3,'Public Inputs'!$B$28:$B$147,$A26,'Public Inputs'!$C$28:$C$147,$B26,'Public Inputs'!$D$28:$D$147,F$24) -> 3.5 | G26: =SUMIFS('Public Inputs'!$K$28:$K$147,'Public Inputs'!$A$28:$A$147,$C$3,'Public Inputs'!$B$28:$B$147,$A26,'Public Inputs'!$C$28:$C$147,$B26,'Public Inputs'!$D$28:$D$147,G$24) -> 2 | H26: =SUMIFS('Public Inputs'!$K$28:$K$147,'Public Inputs'!$A$28:$A$147,$C$3,'Public Inputs'!$B$28:$B$147,$A26,'Public Inputs'!$C$28:$C$147,$B26,'Public Inputs'!$D$28:$D$147,H$24) -> 3 | I26: =SUMIFS('Public Inputs'!$K$28:$K$147,'Public Inputs'!$A$28:$A$147,$C$3,'Public Inputs'!$B$28:$B$147,$A26,'Public Inputs'!$C$28:$C$147,$B26,'Public Inputs'!$D$28:$D$147,I$24) -> 1 | J26: =IF($C$3="Schouwen-Duiveland",INDEX('Public Inputs'!$P$22:$P$31,MATCH($B26,'Public Inputs'!$O$22:$O$31,0)),IF($C$3="Walcheren",INDEX('Public Inputs'!$P$32:$P$41,MATCH($B26,'Public Inputs'!$O$32:$O$41,0)),INDEX('Public Inputs'!$P$42:$P$51,MATCH($B26,'Public Inputs'!$O$42:$O$51,0)))) -> Reinforcement follows a short bridge period while the binding-component stress exceeds the 90% threshold.
A27: Grid operator | B27: Speed and effect on reinforcement bridge gap | D27: =INDEX('Public Inputs'!$C$6:$C$15,MATCH($B27,'Public Inputs'!$B$6:$B$15,0)) -> 0.2 | E27: =INDEX('Public Inputs'!$D$6:$D$15,MATCH($B27,'Public Inputs'!$B$6:$B$15,0)) -> Feasibility | F27: =SUMIFS('Public Inputs'!$K$28:$K$147,'Public Inputs'!$A$28:$A$147,$C$3,'Public Inputs'!$B$28:$B$147,$A27,'Public Inputs'!$C$28:$C$147,$B27,'Public Inputs'!$D$28:$D$147,F$24) -> 1 | G27: =SUMIFS('Public Inputs'!$K$28:$K$147,'Public Inputs'!$A$28:$A$147,$C$3,'Public Inputs'!$B$28:$B$147,$A27,'Public Inputs'!$C$28:$C$147,$B27,'Public Inputs'!$D$28:$D$147,G$24) -> 5 | H27: =SUMIFS('Public Inputs'!$K$28:$K$147,'Public Inputs'!$A$28:$A$147,$C$3,'Public Inputs'!$B$28:$B$147,$A27,'Public Inputs'!$C$28:$C$147,$B27,'Public Inputs'!$D$28:$D$147,H$24) -> 3 | I27: =SUMIFS('Public Inputs'!$K$28:$K$147,'Public Inputs'!$A$28:$A$147,$C$3,'Public Inputs'!$B$28:$B$147,$A27,'Public Inputs'!$C$28:$C$147,$B27,'Public Inputs'!$D$28:$D$147,I$24) -> 1.5 | J27: =IF($C$3="Schouwen-Duiveland",INDEX('Public Inputs'!$P$22:$P$31,MATCH($B27,'Public Inputs'!$O$22:$O$31,0)),IF($C$3="Walcheren",INDEX('Public Inputs'!$P$32:$P$41,MATCH($B27,'Public Inputs'!$O$32:$O$41,0)),INDEX('Public Inputs'!$P$42:$P$51,MATCH($B27,'Public Inputs'!$O$42:$O$51,0)))) -> No relief is provided during the bridge period; the baseline ATC stress remains 97.0%.
A28: Grid operator | B28: Technical and operational readiness | D28: =INDEX('Public Inputs'!$C$6:$C$15,MATCH($B28,'Public Inputs'!$B$6:$B$15,0)) -> 0.15 | E28: =INDEX('Public Inputs'!$D$6:$D$15,MATCH($B28,'Public Inputs'!$B$6:$B$15,0)) -> Maturity | F28: =SUMIFS('Public Inputs'!$K$28:$K$147,'Public Inputs'!$A$28:$A$147,$C$3,'Public Inputs'!$B$28:$B$147,$A28,'Public Inputs'!$C$28:$C$147,$B28,'Public Inputs'!$D$28:$D$147,F$24) -> 5 | G28: =SUMIFS('Public Inputs'!$K$28:$K$147,'Public Inputs'!$A$28:$A$147,$C$3,'Public Inputs'!$B$28:$B$147,$A28,'Public Inputs'!$C$28:$C$147,$B28,'Public Inputs'!$D$28:$D$147,G$24) -> 4 | H28: =SUMIFS('Public Inputs'!$K$28:$K$147,'Public Inputs'!$A$28:$A$147,$C$3,'Public Inputs'!$B$28:$B$147,$A28,'Public Inputs'!$C$28:$C$147,$B28,'Public Inputs'!$D$28:$D$147,H$24) -> 2.5 | I28: =SUMIFS('Public Inputs'!$K$28:$K$147,'Public Inputs'!$A$28:$A$147,$C$3,'Public Inputs'!$B$28:$B$147,$A28,'Public Inputs'!$C$28:$C$147,$B28,'Public Inputs'!$D$28:$D$147,I$24) -> 2 | J28: =IF($C$3="Schouwen-Duiveland",INDEX('Public Inputs'!$P$22:$P$31,MATCH($B28,'Public Inputs'!$O$22:$O$31,0)),IF($C$3="Walcheren",INDEX('Public Inputs'!$P$32:$P$41,MATCH($B28,'Public Inputs'!$O$32:$O$41,0)),INDEX('Public Inputs'!$P$42:$P$51,MATCH($B28,'Public Inputs'!$O$42:$O$51,0)))) -> Regional energy cooperation is developing, which improves the relative readiness of a collective arrangement.
A29: Grid operator | B29: Legal, contractual and policy embeddedness | D29: =INDEX('Public Inputs'!$C$6:$C$15,MATCH($B29,'Public Inputs'!$B$6:$B$15,0)) -> 0.15 | E29: =INDEX('Public Inputs'!$D$6:$D$15,MATCH($B29,'Public Inputs'!$B$6:$B$15,0)) -> Local embeddedness | F29: =SUMIFS('Public Inputs'!$K$28:$K$147,'Public Inputs'!$A$28:$A$147,$C$3,'Public Inputs'!$B$28:$B$147,$A29,'Public Inputs'!$C$28:$C$147,$B29,'Public Inputs'!$D$28:$D$147,F$24) -> 4 | G29: =SUMIFS('Public Inputs'!$K$28:$K$147,'Public Inputs'!$A$28:$A$147,$C$3,'Public Inputs'!$B$28:$B$147,$A29,'Public Inputs'!$C$28:$C$147,$B29,'Public Inputs'!$D$28:$D$147,G$24) -> 3 | H29: =SUMIFS('Public Inputs'!$K$28:$K$147,'Public Inputs'!$A$28:$A$147,$C$3,'Public Inputs'!$B$28:$B$147,$A29,'Public Inputs'!$C$28:$C$147,$B29,'Public Inputs'!$D$28:$D$147,H$24) -> 2 | I29: =SUMIFS('Public Inputs'!$K$28:$K$147,'Public Inputs'!$A$28:$A$147,$C$3,'Public Inputs'!$B$28:$B$147,$A29,'Public Inputs'!$C$28:$C$147,$B29,'Public Inputs'!$D$28:$D$147,I$24) -> 5 | J29: =IF($C$3="Schouwen-Duiveland",INDEX('Public Inputs'!$P$22:$P$31,MATCH($B29,'Public Inputs'!$O$22:$O$31,0)),IF($C$3="Walcheren",INDEX('Public Inputs'!$P$32:$P$41,MATCH($B29,'Public Inputs'!$O$32:$O$41,0)),INDEX('Public Inputs'!$P$42:$P$51,MATCH($B29,'Public Inputs'!$O$42:$O$51,0)))) -> Base score unchanged for this criterion.
A30: Company | B30: Financial attractiveness | D30: =INDEX('Public Inputs'!$C$6:$C$15,MATCH($B30,'Public Inputs'!$B$6:$B$15,0)) -> 0.3 | E30: =INDEX('Public Inputs'!$D$6:$D$15,MATCH($B30,'Public Inputs'!$B$6:$B$15,0)) -> Economic prospects | F30: =SUMIFS('Public Inputs'!$K$28:$K$147,'Public Inputs'!$A$28:$A$147,$C$3,'Public Inputs'!$B$28:$B$147,$A30,'Public Inputs'!$C$28:$C$147,$B30,'Public Inputs'!$D$28:$D$147,F$24) -> 2 | G30: =SUMIFS('Public Inputs'!$K$28:$K$147,'Public Inputs'!$A$28:$A$147,$C$3,'Public Inputs'!$B$28:$B$147,$A30,'Public Inputs'!$C$28:$C$147,$B30,'Public Inputs'!$D$28:$D$147,G$24) -> 5 | H30: =SUMIFS('Public Inputs'!$K$28:$K$147,'Public Inputs'!$A$28:$A$147,$C$3,'Public Inputs'!$B$28:$B$147,$A30,'Public Inputs'!$C$28:$C$147,$B30,'Public Inputs'!$D$28:$D$147,H$24) -> 4 | I30: =SUMIFS('Public Inputs'!$K$28:$K$147,'Public Inputs'!$A$28:$A$147,$C$3,'Public Inputs'!$B$28:$B$147,$A30,'Public Inputs'!$C$28:$C$147,$B30,'Public Inputs'!$D$28:$D$147,I$24) -> 2 | J30: =IF($C$3="Schouwen-Duiveland",INDEX('Public Inputs'!$P$22:$P$31,MATCH($B30,'Public Inputs'!$O$22:$O$31,0)),IF($C$3="Walcheren",INDEX('Public Inputs'!$P$32:$P$41,MATCH($B30,'Public Inputs'!$O$32:$O$41,0)),INDEX('Public Inputs'!$P$42:$P$51,MATCH($B30,'Public Inputs'!$O$42:$O$51,0)))) -> Base score unchanged for this criterion.
A31: Company | B31: Implementation speed and urgency fit | D31: =INDEX('Public Inputs'!$C$6:$C$15,MATCH($B31,'Public Inputs'!$B$6:$B$15,0)) -> 0.2 | E31: =INDEX('Public Inputs'!$D$6:$D$15,MATCH($B31,'Public Inputs'!$B$6:$B$15,0)) -> Feasibility | F31: =SUMIFS('Public Inputs'!$K$28:$K$147,'Public Inputs'!$A$28:$A$147,$C$3,'Public Inputs'!$B$28:$B$147,$A31,'Public Inputs'!$C$28:$C$147,$B31,'Public Inputs'!$D$28:$D$147,F$24) -> 1 | G31: =SUMIFS('Public Inputs'!$K$28:$K$147,'Public Inputs'!$A$28:$A$147,$C$3,'Public Inputs'!$B$28:$B$147,$A31,'Public Inputs'!$C$28:$C$147,$B31,'Public Inputs'!$D$28:$D$147,G$24) -> 4 | H31: =SUMIFS('Public Inputs'!$K$28:$K$147,'Public Inputs'!$A$28:$A$147,$C$3,'Public Inputs'!$B$28:$B$147,$A31,'Public Inputs'!$C$28:$C$147,$B31,'Public Inputs'!$D$28:$D$147,H$24) -> 3 | I31: =SUMIFS('Public Inputs'!$K$28:$K$147,'Public Inputs'!$A$28:$A$147,$C$3,'Public Inputs'!$B$28:$B$147,$A31,'Public Inputs'!$C$28:$C$147,$B31,'Public Inputs'!$D$28:$D$147,I$24) -> 1 | J31: =IF($C$3="Schouwen-Duiveland",INDEX('Public Inputs'!$P$22:$P$31,MATCH($B31,'Public Inputs'!$O$22:$O$31,0)),IF($C$3="Walcheren",INDEX('Public Inputs'!$P$32:$P$41,MATCH($B31,'Public Inputs'!$O$32:$O$41,0)),INDEX('Public Inputs'!$P$42:$P$51,MATCH($B31,'Public Inputs'!$O$42:$O$51,0)))) -> Base score unchanged for this criterion.
A32: Company | B32: Knowledge and organisational burden | D32: =INDEX('Public Inputs'!$C$6:$C$15,MATCH($B32,'Public Inputs'!$B$6:$B$15,0)) -> 0.2 | E32: =INDEX('Public Inputs'!$D$6:$D$15,MATCH($B32,'Public Inputs'!$B$6:$B$15,0)) -> Scalability + feasibility | F32: =SUMIFS('Public Inputs'!$K$28:$K$147,'Public Inputs'!$A$28:$A$147,$C$3,'Public Inputs'!$B$28:$B$147,$A32,'Public Inputs'!$C$28:$C$147,$B32,'Public Inputs'!$D$28:$D$147,F$24) -> 4 | G32: =SUMIFS('Public Inputs'!$K$28:$K$147,'Public Inputs'!$A$28:$A$147,$C$3,'Public Inputs'!$B$28:$B$147,$A32,'Public Inputs'!$C$28:$C$147,$B32,'Public Inputs'!$D$28:$D$147,G$24) -> 3 | H32: =SUMIFS('Public Inputs'!$K$28:$K$147,'Public Inputs'!$A$28:$A$147,$C$3,'Public Inputs'!$B$28:$B$147,$A32,'Public Inputs'!$C$28:$C$147,$B32,'Public Inputs'!$D$28:$D$147,H$24) -> 2.5 | I32: =SUMIFS('Public Inputs'!$K$28:$K$147,'Public Inputs'!$A$28:$A$147,$C$3,'Public Inputs'!$B$28:$B$147,$A32,'Public Inputs'!$C$28:$C$147,$B32,'Public Inputs'!$D$28:$D$147,I$24) -> 5 | J32: =IF($C$3="Schouwen-Duiveland",INDEX('Public Inputs'!$P$22:$P$31,MATCH($B32,'Public Inputs'!$O$22:$O$31,0)),IF($C$3="Walcheren",INDEX('Public Inputs'!$P$32:$P$41,MATCH($B32,'Public Inputs'!$O$32:$O$41,0)),INDEX('Public Inputs'!$P$42:$P$51,MATCH($B32,'Public Inputs'!$O$42:$O$51,0)))) -> Regional groups and municipal facilitation can reduce the coordination burden.
A33: Company | B33: Autonomy and dependency | D33: =INDEX('Public Inputs'!$C$6:$C$15,MATCH($B33,'Public Inputs'!$B$6:$B$15,0)) -> 0.15 | E33: =INDEX('Public Inputs'!$D$6:$D$15,MATCH($B33,'Public Inputs'!$B$6:$B$15,0)) -> Regional relatedness + local embeddedness | F33: =SUMIFS('Public Inputs'!$K$28:$K$147,'Public Inputs'!$A$28:$A$147,$C$3,'Public Inputs'!$B$28:$B$147,$A33,'Public Inputs'!$C$28:$C$147,$B33,'Public Inputs'!$D$28:$D$147,F$24) -> 3 | G33: =SUMIFS('Public Inputs'!$K$28:$K$147,'Public Inputs'!$A$28:$A$147,$C$3,'Public Inputs'!$B$28:$B$147,$A33,'Public Inputs'!$C$28:$C$147,$B33,'Public Inputs'!$D$28:$D$147,G$24) -> 5 | H33: =SUMIFS('Public Inputs'!$K$28:$K$147,'Public Inputs'!$A$28:$A$147,$C$3,'Public Inputs'!$B$28:$B$147,$A33,'Public Inputs'!$C$28:$C$147,$B33,'Public Inputs'!$D$28:$D$147,H$24) -> 2.5 | I33: =SUMIFS('Public Inputs'!$K$28:$K$147,'Public Inputs'!$A$28:$A$147,$C$3,'Public Inputs'!$B$28:$B$147,$A33,'Public Inputs'!$C$28:$C$147,$B33,'Public Inputs'!$D$28:$D$147,I$24) -> 5 | J33: =IF($C$3="Schouwen-Duiveland",INDEX('Public Inputs'!$P$22:$P$31,MATCH($B33,'Public Inputs'!$O$22:$O$31,0)),IF($C$3="Walcheren",INDEX('Public Inputs'!$P$32:$P$41,MATCH($B33,'Public Inputs'!$O$32:$O$41,0)),INDEX('Public Inputs'!$P$42:$P$51,MATCH($B33,'Public Inputs'!$O$42:$O$51,0)))) -> Existing cooperation reduces the dependency objection identified by participating companies.
A34: Company | B34: Sustainability, image and strategic risk | D34: =INDEX('Public Inputs'!$C$6:$C$15,MATCH($B34,'Public Inputs'!$B$6:$B$15,0)) -> 0.15 | E34: =INDEX('Public Inputs'!$D$6:$D$15,MATCH($B34,'Public Inputs'!$B$6:$B$15,0)) -> Climate and energy impacts | F34: =SUMIFS('Public Inputs'!$K$28:$K$147,'Public Inputs'!$A$28:$A$147,$C$3,'Public Inputs'!$B$28:$B$147,$A34,'Public Inputs'!$C$28:$C$147,$B34,'Public Inputs'!$D$28:$D$147,F$24) -> 3 | G34: =SUMIFS('Public Inputs'!$K$28:$K$147,'Public Inputs'!$A$28:$A$147,$C$3,'Public Inputs'!$B$28:$B$147,$A34,'Public Inputs'!$C$28:$C$147,$B34,'Public Inputs'!$D$28:$D$147,G$24) -> 4 | H34: =SUMIFS('Public Inputs'!$K$28:$K$147,'Public Inputs'!$A$28:$A$147,$C$3,'Public Inputs'!$B$28:$B$147,$A34,'Public Inputs'!$C$28:$C$147,$B34,'Public Inputs'!$D$28:$D$147,H$24) -> 5 | I34: =SUMIFS('Public Inputs'!$K$28:$K$147,'Public Inputs'!$A$28:$A$147,$C$3,'Public Inputs'!$B$28:$B$147,$A34,'Public Inputs'!$C$28:$C$147,$B34,'Public Inputs'!$D$28:$D$147,I$24) -> 1 | J34: =IF($C$3="Schouwen-Duiveland",INDEX('Public Inputs'!$P$22:$P$31,MATCH($B34,'Public Inputs'!$O$22:$O$31,0)),IF($C$3="Walcheren",INDEX('Public Inputs'!$P$32:$P$41,MATCH($B34,'Public Inputs'!$O$32:$O$41,0)),INDEX('Public Inputs'!$P$42:$P$51,MATCH($B34,'Public Inputs'!$O$42:$O$51,0)))) -> Base score unchanged for this criterion.
A36: Interpretation and public-use note
A37: Response option is the umbrella term for the four alternatives. Battery + EMS and the Group Transport Agreement are the flexibility-solution subset; conventional grid reinforcement and no additional intervention are not flexibility solutions.
A38: Flexibility is assessed as a possible complement to or bridge towards reinforcement. It is not assumed to replace reinforcement where the percentage-based grid evidence indicates that physical capacity remains necessary.
A39: Confidentiality: the workbook contains no village names, station names or codes, absolute load/capacity values, exact project costs, internal source filenames, hidden sheets or external links.

Sheet Public Inputs
A1: Public TAPIR Inputs and Scoring Logic | B1: Public TAPIR Inputs and Scoring Logic | C1: Public TAPIR Inputs and Scoring Logic | D1: Public TAPIR Inputs and Scoring Logic | E1: Public TAPIR Inputs and Scoring Logic | F1: Public TAPIR Inputs and Scoring Logic | G1: Public TAPIR Inputs and Scoring Logic | H1: Public TAPIR Inputs and Scoring Logic | I1: Public TAPIR Inputs and Scoring Logic | J1: Public TAPIR Inputs and Scoring Logic | K1: Public TAPIR Inputs and Scoring Logic | L1: Public TAPIR Inputs and Scoring Logic | M1: Public TAPIR Inputs and Scoring Logic | N1: Public TAPIR Inputs and Scoring Logic | O1: Public TAPIR Inputs and Scoring Logic | P1: Public TAPIR Inputs and Scoring Logic | Q1: Public TAPIR Inputs and Scoring Logic | R1: Public TAPIR Inputs and Scoring Logic | S1: Public TAPIR Inputs and Scoring Logic | T1: Public TAPIR Inputs and Scoring Logic
A2: Public version: village names and grid assets are anonymised | B2: Public version: village names and grid assets are anonymised; absolute load, capacity, project-cost and station-level source data are excluded. | C2: Public version: village names and grid assets are anonymised; absolute load, capacity, project-cost and station-level source data are excluded. | D2: Public version: village names and grid assets are anonymised; absolute load, capacity, project-cost and station-level source data are excluded. | E2: Public version: village names and grid assets are anonymised; absolute load, capacity, project-cost and station-level source data are excluded. | F2: Public version: village names and grid assets are anonymised; absolute load, capacity, project-cost and station-level source data are excluded. | G2: Public version: village names and grid assets are anonymised; absolute load, capacity, project-cost and station-level source data are excluded. | H2: Public version: village names and grid assets are anonymised; absolute load, capacity, project-cost and station-level source data are excluded. | I2: Public version: village names and grid assets are anonymised; absolute load, capacity, project-cost and station-level source data are excluded. | J2: Public version: village names and grid assets are anonymised; absolute load, capacity, project-cost and station-level source data are excluded. | K2: Public version: village names and grid assets are anonymised; absolute load, capacity, project-cost and station-level source data are excluded. | L2: Public version: village names and grid assets are anonymised; absolute load, capacity, project-cost and station-level source data are excluded. | M2: Public version: village names and grid assets are anonymised; absolute load, capacity, project-cost and station-level source data are excluded. | N2: Public version: village names and grid assets are anonymised; absolute load, capacity, project-cost and station-level source data are excluded. | O2: Public version: village names and grid assets are anonymised; absolute load, capacity, project-cost and station-level source data are excluded. | P2: Public version: village names and grid assets are anonymised; absolute load, capacity, project-cost and station-level source data are excluded. | Q2: Public version: village names and grid assets are anonymised; absolute load, capacity, project-cost and station-level source data are excluded. | R2: Public version: village names and grid assets are anonymised; absolute load, capacity, project-cost and station-level source data are excluded. | S2: Public version: village names and grid assets are anonymised; absolute load, capacity, project-cost and station-level source data are excluded. | T2: Public version: village names and grid assets are anonymised; absolute load, capacity, project-cost and station-level source data are excluded.
A4: Editable base criteria, weights and response-option scores | B4: Editable base criteria, weights and response-option scores | C4: Editable base criteria, weights and response-option scores | D4: Editable base criteria, weights and response-option scores | E4: Editable base criteria, weights and response-option scores | F4: Editable base criteria, weights and response-option scores | G4: Editable base criteria, weights and response-option scores | H4: Editable base criteria, weights and response-option scores | I4: Editable base criteria, weights and response-option scores | N4: Case-specific pathway result library | O4: Case-specific pathway result library | P4: Case-specific pathway result library | Q4: Case-specific pathway result library | R4: Case-specific pathway result library | S4: Case-specific pathway result library | T4: Case-specific pathway result library
A5: Actor | B5: Criterion | C5: Weight | D5: TAPIR factor | E5: KPI / evidence basis | F5: Conventional grid reinforcement | G5: Battery + EMS | H5: Group Transport Agreement | I5: No additional intervention | N5: Case region | O5: Response option | P5: Grid-operator score | Q5: Company score | R5: Equal actor average | S5: Result | T5: Lookup key
A6: Grid operator | B6: Grid-operator life-cycle cost and investment effect | C6: 0.3 | D6: Economic prospects | E6: Relative investment implications, flexibility cost and potential reinforcement deferral; absolute project values are excluded. | F6: 2 | G6: 4 | H6: 4 | I6: 5 | N6: Schouwen-Duiveland | O6: Conventional grid reinforcement | P6: =SUMIFS($L$28:$L$147,$A$28:$A$147,$N6,$B$28:$B$147,"Grid operator",$D$28:$D$147,$O6)/SUMIFS($J$28:$J$147,$A$28:$A$147,$N6,$B$28:$B$147,"Grid operator",$D$28:$D$147,$O6) -> 2.85 | Q6: =SUMIFS($L$28:$L$147,$A$28:$A$147,$N6,$B$28:$B$147,"Company",$D$28:$D$147,$O6)/SUMIFS($J$28:$J$147,$A$28:$A$147,$N6,$B$28:$B$147,"Company",$D$28:$D$147,$O6) -> 2.5 | R6: =(P6+Q6)/2 -> 2.675 | S6: =IF(R6=_xludf.MAXIFS($R$6:$R$17,$N$6:$N$17,N6),"Preferred response option","—") -> #NAME? | T6: Schouwen-Duiveland|Conventional grid reinforcement
A7: Grid operator | B7: Timing, duration, reliability and predictability | C7: 0.2 | D7: Maturity | E7: Threshold exceedance pattern, timing, availability and asset life, expressed without absolute load data. | F7: 4 | G7: 2 | H7: 3 | I7: 1 | N7: Schouwen-Duiveland | O7: Battery + EMS | P7: =SUMIFS($L$28:$L$147,$A$28:$A$147,$N7,$B$28:$B$147,"Grid operator",$D$28:$D$147,$O7)/SUMIFS($J$28:$J$147,$A$28:$A$147,$N7,$B$28:$B$147,"Grid operator",$D$28:$D$147,$O7) -> 3.65 | Q7: =SUMIFS($L$28:$L$147,$A$28:$A$147,$N7,$B$28:$B$147,"Company",$D$28:$D$147,$O7)/SUMIFS($J$28:$J$147,$A$28:$A$147,$N7,$B$28:$B$147,"Company",$D$28:$D$147,$O7) -> 4.25 | R7: =(P7+Q7)/2 -> 3.95 | S7: =IF(R7=_xludf.MAXIFS($R$6:$R$17,$N$6:$N$17,N7),"Preferred response option","—") -> #NAME? | T7: Schouwen-Duiveland|Battery + EMS
A8: Grid operator | B8: Speed and effect on reinforcement bridge gap | C8: 0.2 | D8: Feasibility | E8: Whether an option is available during the bridge period and reduces ATC stress to 90% or below. | F8: 1 | G8: 5 | H8: 3 | I8: 2 | N8: Schouwen-Duiveland | O8: Group Transport Agreement | P8: =SUMIFS($L$28:$L$147,$A$28:$A$147,$N8,$B$28:$B$147,"Grid operator",$D$28:$D$147,$O8)/SUMIFS($J$28:$J$147,$A$28:$A$147,$N8,$B$28:$B$147,"Grid operator",$D$28:$D$147,$O8) -> 3.075 | Q8: =SUMIFS($L$28:$L$147,$A$28:$A$147,$N8,$B$28:$B$147,"Company",$D$28:$D$147,$O8)/SUMIFS($J$28:$J$147,$A$28:$A$147,$N8,$B$28:$B$147,"Company",$D$28:$D$147,$O8) -> 3.425 | R8: =(P8+Q8)/2 -> 3.25 | S8: =IF(R8=_xludf.MAXIFS($R$6:$R$17,$N$6:$N$17,N8),"Preferred response option","—") -> #NAME? | T8: Schouwen-Duiveland|Group Transport Agreement
A9: Grid operator | B9: Technical and operational readiness | C9: 0.15 | D9: Maturity | E9: Installed assets, control systems and the operational status of flexibility arrangements. | F9: 5 | G9: 4 | H9: 2 | I9: 2 | N9: Schouwen-Duiveland | O9: No additional intervention | P9: =SUMIFS($L$28:$L$147,$A$28:$A$147,$N9,$B$28:$B$147,"Grid operator",$D$28:$D$147,$O9)/SUMIFS($J$28:$J$147,$A$28:$A$147,$N9,$B$28:$B$147,"Grid operator",$D$28:$D$147,$O9) -> 3.05 | Q9: =SUMIFS($L$28:$L$147,$A$28:$A$147,$N9,$B$28:$B$147,"Company",$D$28:$D$147,$O9)/SUMIFS($J$28:$J$147,$A$28:$A$147,$N9,$B$28:$B$147,"Company",$D$28:$D$147,$O9) -> 2.7 | R9: =(P9+Q9)/2 -> 2.875 | S9: =IF(R9=_xludf.MAXIFS($R$6:$R$17,$N$6:$N$17,N9),"Preferred response option","—") -> #NAME? | T9: Schouwen-Duiveland|No additional intervention
A10: Grid operator | B10: Legal, contractual and policy embeddedness | C10: 0.15 | D10: Local embeddedness | E10: Legal status, agreements, connection conditions and policy alignment. | F10: 4 | G10: 3 | H10: 2 | I10: 5 | N10: Walcheren | O10: Conventional grid reinforcement | P10: =SUMIFS($L$28:$L$147,$A$28:$A$147,$N10,$B$28:$B$147,"Grid operator",$D$28:$D$147,$O10)/SUMIFS($J$28:$J$147,$A$28:$A$147,$N10,$B$28:$B$147,"Grid operator",$D$28:$D$147,$O10) -> 2.85 | Q10: =SUMIFS($L$28:$L$147,$A$28:$A$147,$N10,$B$28:$B$147,"Company",$D$28:$D$147,$O10)/SUMIFS($J$28:$J$147,$A$28:$A$147,$N10,$B$28:$B$147,"Company",$D$28:$D$147,$O10) -> 2.5 | R10: =(P10+Q10)/2 -> 2.675 | S10: =IF(R10=_xludf.MAXIFS($R$6:$R$17,$N$6:$N$17,N10),"Preferred response option","—") -> #NAME? | T10: Walcheren|Conventional grid reinforcement
A11: Company | B11: Financial attractiveness | C11: 0.3 | D11: Economic prospects | E11: Relative cost, benefit, payback and compensation considerations; confidential monetary values are excluded. | F11: 2 | G11: 5 | H11: 4 | I11: 2 | N11: Walcheren | O11: Battery + EMS | P11: =SUMIFS($L$28:$L$147,$A$28:$A$147,$N11,$B$28:$B$147,"Grid operator",$D$28:$D$147,$O11)/SUMIFS($J$28:$J$147,$A$28:$A$147,$N11,$B$28:$B$147,"Grid operator",$D$28:$D$147,$O11) -> 3.975 | Q11: =SUMIFS($L$28:$L$147,$A$28:$A$147,$N11,$B$28:$B$147,"Company",$D$28:$D$147,$O11)/SUMIFS($J$28:$J$147,$A$28:$A$147,$N11,$B$28:$B$147,"Company",$D$28:$D$147,$O11) -> 4.45 | R11: =(P11+Q11)/2 -> 4.2125 | S11: =IF(R11=_xludf.MAXIFS($R$6:$R$17,$N$6:$N$17,N11),"Preferred response option","—") -> #NAME? | T11: Walcheren|Battery + EMS
A12: Company | B12: Implementation speed and urgency fit | C12: 0.2 | D12: Feasibility | E12: Case-specific lead time and availability before the constraint becomes binding. | F12: 1 | G12: 4 | H12: 3 | I12: 1 | N12: Walcheren | O12: Group Transport Agreement | P12: =SUMIFS($L$28:$L$147,$A$28:$A$147,$N12,$B$28:$B$147,"Grid operator",$D$28:$D$147,$O12)/SUMIFS($J$28:$J$147,$A$28:$A$147,$N12,$B$28:$B$147,"Grid operator",$D$28:$D$147,$O12) -> 3.05 | Q12: =SUMIFS($L$28:$L$147,$A$28:$A$147,$N12,$B$28:$B$147,"Company",$D$28:$D$147,$O12)/SUMIFS($J$28:$J$147,$A$28:$A$147,$N12,$B$28:$B$147,"Company",$D$28:$D$147,$O12) -> 3.3 | R12: =(P12+Q12)/2 -> 3.175 | S12: =IF(R12=_xludf.MAXIFS($R$6:$R$17,$N$6:$N$17,N12),"Preferred response option","—") -> #NAME? | T12: Walcheren|Group Transport Agreement
A13: Company | B13: Knowledge and organisational burden | C13: 0.2 | D13: Scalability + feasibility | E13: Advice needs, actors involved, management time and coordination requirements. | F13: 4 | G13: 3 | H13: 2 | I13: 5 | N13: Walcheren | O13: No additional intervention | P13: =SUMIFS($L$28:$L$147,$A$28:$A$147,$N13,$B$28:$B$147,"Grid operator",$D$28:$D$147,$O13)/SUMIFS($J$28:$J$147,$A$28:$A$147,$N13,$B$28:$B$147,"Grid operator",$D$28:$D$147,$O13) -> 3.05 | Q13: =SUMIFS($L$28:$L$147,$A$28:$A$147,$N13,$B$28:$B$147,"Company",$D$28:$D$147,$O13)/SUMIFS($J$28:$J$147,$A$28:$A$147,$N13,$B$28:$B$147,"Company",$D$28:$D$147,$O13) -> 2.7 | R13: =(P13+Q13)/2 -> 2.875 | S13: =IF(R13=_xludf.MAXIFS($R$6:$R$17,$N$6:$N$17,N13),"Preferred response option","—") -> #NAME? | T13: Walcheren|No additional intervention
A14: Company | B14: Autonomy and dependency | C14: 0.15 | D14: Regional relatedness + local embeddedness | E14: Asset control, dependence on other actors and collective decision requirements. | F14: 3 | G14: 5 | H14: 2 | I14: 5 | N14: West-Zeeuws-Vlaanderen | O14: Conventional grid reinforcement | P14: =SUMIFS($L$28:$L$147,$A$28:$A$147,$N14,$B$28:$B$147,"Grid operator",$D$28:$D$147,$O14)/SUMIFS($J$28:$J$147,$A$28:$A$147,$N14,$B$28:$B$147,"Grid operator",$D$28:$D$147,$O14) -> 2.85 | Q14: =SUMIFS($L$28:$L$147,$A$28:$A$147,$N14,$B$28:$B$147,"Company",$D$28:$D$147,$O14)/SUMIFS($J$28:$J$147,$A$28:$A$147,$N14,$B$28:$B$147,"Company",$D$28:$D$147,$O14) -> 2.5 | R14: =(P14+Q14)/2 -> 2.675 | S14: =IF(R14=_xludf.MAXIFS($R$6:$R$17,$N$6:$N$17,N14),"Preferred response option","—") -> #NAME? | T14: West-Zeeuws-Vlaanderen|Conventional grid reinforcement
A15: Company | B15: Sustainability, image and strategic risk | C15: 0.15 | D15: Climate and energy impacts | E15: Electrification, renewable-energy use, policy alignment and strategic fit. | F15: 3 | G15: 4 | H15: 5 | I15: 1 | N15: West-Zeeuws-Vlaanderen | O15: Battery + EMS | P15: =SUMIFS($L$28:$L$147,$A$28:$A$147,$N15,$B$28:$B$147,"Grid operator",$D$28:$D$147,$O15)/SUMIFS($J$28:$J$147,$A$28:$A$147,$N15,$B$28:$B$147,"Grid operator",$D$28:$D$147,$O15) -> 3.8 | Q15: =SUMIFS($L$28:$L$147,$A$28:$A$147,$N15,$B$28:$B$147,"Company",$D$28:$D$147,$O15)/SUMIFS($J$28:$J$147,$A$28:$A$147,$N15,$B$28:$B$147,"Company",$D$28:$D$147,$O15) -> 4.35 | R15: =(P15+Q15)/2 -> 4.075 | S15: =IF(R15=_xludf.MAXIFS($R$6:$R$17,$N$6:$N$17,N15),"Preferred response option","—") -> #NAME? | T15: West-Zeeuws-Vlaanderen|Battery + EMS
N16: West-Zeeuws-Vlaanderen | O16: Group Transport Agreement | P16: =SUMIFS($L$28:$L$147,$A$28:$A$147,$N16,$B$28:$B$147,"Grid operator",$D$28:$D$147,$O16)/SUMIFS($J$28:$J$147,$A$28:$A$147,$N16,$B$28:$B$147,"Grid operator",$D$28:$D$147,$O16) -> 2.975 | Q16: =SUMIFS($L$28:$L$147,$A$28:$A$147,$N16,$B$28:$B$147,"Company",$D$28:$D$147,$O16)/SUMIFS($J$28:$J$147,$A$28:$A$147,$N16,$B$28:$B$147,"Company",$D$28:$D$147,$O16) -> 3.225 | R16: =(P16+Q16)/2 -> 3.1 | S16: =IF(R16=_xludf.MAXIFS($R$6:$R$17,$N$6:$N$17,N16),"Preferred response option","—") -> #NAME? | T16: West-Zeeuws-Vlaanderen|Group Transport Agreement
A17: Weight validation | B17: Grid operator | C17: =SUMIF($A$6:$A$15,"Grid operator",$C$6:$C$15) -> 1 | D17: Company | E17: =SUMIF($A$6:$A$15,"Company",$C$6:$C$15) -> 1 | F17: =IF(AND(ABS(C17-1)<0.0001,ABS(E17-1)<0.0001),"OK — both actors total 100%","Review weights") -> OK — both actors total 100% | N17: West-Zeeuws-Vlaanderen | O17: No additional intervention | P17: =SUMIFS($L$28:$L$147,$A$28:$A$147,$N17,$B$28:$B$147,"Grid operator",$D$28:$D$147,$O17)/SUMIFS($J$28:$J$147,$A$28:$A$147,$N17,$B$28:$B$147,"Grid operator",$D$28:$D$147,$O17) -> 3.05 | Q17: =SUMIFS($L$28:$L$147,$A$28:$A$147,$N17,$B$28:$B$147,"Company",$D$28:$D$147,$O17)/SUMIFS($J$28:$J$147,$A$28:$A$147,$N17,$B$28:$B$147,"Company",$D$28:$D$147,$O17) -> 2.7 | R17: =(P17+Q17)/2 -> 2.875 | S17: =IF(R17=_xludf.MAXIFS($R$6:$R$17,$N$6:$N$17,N17),"Preferred response option","—") -> #NAME? | T17: West-Zeeuws-Vlaanderen|No additional intervention
A20: Anonymised case indicators — load values expressed only as percentages | B20: Anonymised case indicators — load values expressed only as percentages | C20: Anonymised case indicators — load values expressed only as percentages | D20: Anonymised case indicators — load values expressed only as percentages | E20: Anonymised case indicators — load values expressed only as percentages | F20: Anonymised case indicators — load values expressed only as percentages | G20: Anonymised case indicators — load values expressed only as percentages | H20: Anonymised case indicators — load values expressed only as percentages | I20: Anonymised case indicators — load values expressed only as percentages | J20: Anonymised case indicators — load values expressed only as percentages | K20: Anonymised case indicators — load values expressed only as percentages | L20: Anonymised case indicators — load values expressed only as percentages | M20: Anonymised case indicators — load values expressed only as percentages | N20: Selected-case adjustment summaries | O20: Selected-case adjustment summaries | P20: Selected-case adjustment summaries | Q20: Selected-case adjustment summaries
A21: Case region | B21: Public village label | C21: Data coverage | E21: Medium-voltage station ATC | F21: Main distribution station baseline ATC | G21: After battery + EMS | H21: After Group Transport Agreement | I21: Evidence basis | J21: Threshold result | K21: Public grid summary | L21: Interview synthesis | M21: Public-data note | N21: Case region | O21: Criterion | P21: Public adjustment summary | Q21: Lookup key
A22: Schouwen-Duiveland | B22: Village 1 | C22: 1 | E22: 0.887 | F22: 0.97 | G22: 0.914 | H22: 0.916 | I22: Forecast percentage | J22: Neither flexibility solution clears the 90% threshold | K22: The main distribution station is forecast to exceed the threshold before planned reinforcement. Both flexibility solutions reduce stress, but neither removes the exceedance; reinforcement therefore remains necessary. | L22: Interview synthesis indicates that existing regional cooperation may lower the coordination burden for a collective agreement, while companies continue to value autonomy and options that can be implemented quickly. | M22: All load and capacity indicators are normalised percentages. Absolute electrical values, station identifiers and exact project inputs have been removed. | N22: Schouwen-Duiveland | O22: Grid-operator life-cycle cost and investment effect | P22: Base score unchanged for this criterion. | Q22: Schouwen-Duiveland|Grid-operator life-cycle cost and investment effect
A23: Walcheren | B23: Village 2 | C23: 1 | E23: 0.823 | F23: 0.948 | G23: 0.883 | H23: 0.891 | I23: Measured percentage test | J23: Both flexibility solutions clear the 90% threshold in the measured test | K23: Short peaks at the main distribution station are reduced below the threshold by both flexibility solutions. The margins are narrow, and performance over the full period remains uncertain without a forward series. | L23: Interview synthesis indicates that battery and EMS operation is already established at several companies. Collective initiatives are less mature and place more coordination responsibility on participating companies. | M23: All load and capacity indicators are normalised percentages. Absolute electrical values, station identifiers and exact project inputs have been removed. | N23: Schouwen-Duiveland | O23: Timing, duration, reliability and predictability | P23: Reinforcement follows a short bridge period while the binding-component stress exceeds the 90% threshold. | Q23: Schouwen-Duiveland|Timing, duration, reliability and predictability
A24: West-Zeeuws-Vlaanderen | B24: Village 3 | C24: 0.84109589 | E24: 0.539 | F24: 0.906 | G24: 0.861 | H24: 0.858 | I24: Measured percentage test | J24: Both flexibility solutions clear the 90% threshold initially; future coverage is uncertain | K24: The main distribution station marginally exceeds the threshold in the measured profile. Both flexibility solutions clear the threshold initially, but the longer-term result and the link to reinforcement remain uncertain. | L24: Interview synthesis indicates that batteries are under consideration, whereas central company decision structures and limited collective governance increase the coordination burden for a Group Transport Agreement. | M24: All load and capacity indicators are normalised percentages. Absolute electrical values, station identifiers and exact project inputs have been removed. | N24: Schouwen-Duiveland | O24: Speed and effect on reinforcement bridge gap | P24: No relief is provided during the bridge period; the baseline ATC stress remains 97.0%. | Q24: Schouwen-Duiveland|Speed and effect on reinforcement bridge gap
N25: Schouwen-Duiveland | O25: Technical and operational readiness | P25: Regional energy cooperation is developing, which improves the relative readiness of a collective arrangement. | Q25: Schouwen-Duiveland|Technical and operational readiness
A26: Case-specific regional adjustments and transparent score calculation | B26: Case-specific regional adjustments and transparent score calculation | C26: Case-specific regional adjustments and transparent score calculation | D26: Case-specific regional adjustments and transparent score calculation | E26: Case-specific regional adjustments and transparent score calculation | F26: Case-specific regional adjustments and transparent score calculation | G26: Case-specific regional adjustments and transparent score calculation | H26: Case-specific regional adjustments and transparent score calculation | I26: Case-specific regional adjustments and transparent score calculation | J26: Case-specific regional adjustments and transparent score calculation | K26: Case-specific regional adjustments and transparent score calculation | L26: Case-specific regional adjustments and transparent score calculation | N26: Schouwen-Duiveland | O26: Legal, contractual and policy embeddedness | P26: Base score unchanged for this criterion. | Q26: Schouwen-Duiveland|Legal, contractual and policy embeddedness
A27: Case region | B27: Actor | C27: Criterion | D27: Response option | E27: Regional adjustment | F27: Public evidence | G27: Evidence type | H27: Calculation key | I27: Base score | J27: Weight | K27: Adjusted score | L27: Weighted contribution | N27: Schouwen-Duiveland | O27: Financial attractiveness | P27: Base score unchanged for this criterion. | Q27: Schouwen-Duiveland|Financial attractiveness
A28: Schouwen-Duiveland | B28: Grid operator | C28: Grid-operator life-cycle cost and investment effect | D28: Conventional grid reinforcement | E28: 0 | F28: Base score unchanged for this case. | G28: Base TAPIR assessment | H28: Schouwen-Duiveland|Grid operator|Grid-operator life-cycle cost and investment effect|Conventional grid reinforcement | I28: =INDEX($F$6:$I$15,MATCH($C28,$B$6:$B$15,0),MATCH($D28,$F$5:$I$5,0)) -> 2 | J28: =INDEX($C$6:$C$15,MATCH($C28,$B$6:$B$15,0)) -> 0.3 | K28: =MAX(1,MIN(5,I28+E28)) -> 2 | L28: =J28*K28 -> 0.6 | N28: Schouwen-Duiveland | O28: Implementation speed and urgency fit | P28: Base score unchanged for this criterion. | Q28: Schouwen-Duiveland|Implementation speed and urgency fit
A29: Schouwen-Duiveland | B29: Grid operator | C29: Grid-operator life-cycle cost and investment effect | D29: Battery + EMS | E29: 0 | F29: Base score unchanged for this case. | G29: Base TAPIR assessment | H29: Schouwen-Duiveland|Grid operator|Grid-operator life-cycle cost and investment effect|Battery + EMS | I29: =INDEX($F$6:$I$15,MATCH($C29,$B$6:$B$15,0),MATCH($D29,$F$5:$I$5,0)) -> 4 | J29: =INDEX($C$6:$C$15,MATCH($C29,$B$6:$B$15,0)) -> 0.3 | K29: =MAX(1,MIN(5,I29+E29)) -> 4 | L29: =J29*K29 -> 1.2 | N29: Schouwen-Duiveland | O29: Knowledge and organisational burden | P29: Regional groups and municipal facilitation can reduce the coordination burden. | Q29: Schouwen-Duiveland|Knowledge and organisational burden
A30: Schouwen-Duiveland | B30: Grid operator | C30: Grid-operator life-cycle cost and investment effect | D30: Group Transport Agreement | E30: 0 | F30: Base score unchanged for this case. | G30: Base TAPIR assessment | H30: Schouwen-Duiveland|Grid operator|Grid-operator life-cycle cost and investment effect|Group Transport Agreement | I30: =INDEX($F$6:$I$15,MATCH($C30,$B$6:$B$15,0),MATCH($D30,$F$5:$I$5,0)) -> 4 | J30: =INDEX($C$6:$C$15,MATCH($C30,$B$6:$B$15,0)) -> 0.3 | K30: =MAX(1,MIN(5,I30+E30)) -> 4 | L30: =J30*K30 -> 1.2 | N30: Schouwen-Duiveland | O30: Autonomy and dependency | P30: Existing cooperation reduces the dependency objection identified by participating companies. | Q30: Schouwen-Duiveland|Autonomy and dependency
A31: Schouwen-Duiveland | B31: Grid operator | C31: Grid-operator life-cycle cost and investment effect | D31: No additional intervention | E31: 0 | F31: Base score unchanged for this case. | G31: Base TAPIR assessment | H31: Schouwen-Duiveland|Grid operator|Grid-operator life-cycle cost and investment effect|No additional intervention | I31: =INDEX($F$6:$I$15,MATCH($C31,$B$6:$B$15,0),MATCH($D31,$F$5:$I$5,0)) -> 5 | J31: =INDEX($C$6:$C$15,MATCH($C31,$B$6:$B$15,0)) -> 0.3 | K31: =MAX(1,MIN(5,I31+E31)) -> 5 | L31: =J31*K31 -> 1.5 | N31: Schouwen-Duiveland | O31: Sustainability, image and strategic risk | P31: Base score unchanged for this criterion. | Q31: Schouwen-Duiveland|Sustainability, image and strategic risk
A32: Schouwen-Duiveland | B32: Grid operator | C32: Timing, duration, reliability and predictability | D32: Conventional grid reinforcement | E32: -0.5 | F32: Reinforcement follows a short bridge period while the binding-component stress exceeds the 90% threshold. | G32: Percentage-based grid assessment | H32: Schouwen-Duiveland|Grid operator|Timing, duration, reliability and predictability|Conventional grid reinforcement | I32: =INDEX($F$6:$I$15,MATCH($C32,$B$6:$B$15,0),MATCH($D32,$F$5:$I$5,0)) -> 4 | J32: =INDEX($C$6:$C$15,MATCH($C32,$B$6:$B$15,0)) -> 0.2 | K32: =MAX(1,MIN(5,I32+E32)) -> 3.5 | L32: =J32*K32 -> 0.7 | N32: Walcheren | O32: Grid-operator life-cycle cost and investment effect | P32: The measured ATC stress decreases from 94.8% to 88.3%, below the 90% threshold. | The measured ATC stress decreases from 94.8% to 89.1%, below the 90% threshold. | Q32: Walcheren|Grid-operator life-cycle cost and investment effect
A33: Schouwen-Duiveland | B33: Grid operator | C33: Timing, duration, reliability and predictability | D33: Battery + EMS | E33: 0 | F33: Base score unchanged for this case. | G33: Base TAPIR assessment | H33: Schouwen-Duiveland|Grid operator|Timing, duration, reliability and predictability|Battery + EMS | I33: =INDEX($F$6:$I$15,MATCH($C33,$B$6:$B$15,0),MATCH($D33,$F$5:$I$5,0)) -> 2 | J33: =INDEX($C$6:$C$15,MATCH($C33,$B$6:$B$15,0)) -> 0.2 | K33: =MAX(1,MIN(5,I33+E33)) -> 2 | L33: =J33*K33 -> 0.4 | N33: Walcheren | O33: Timing, duration, reliability and predictability | P33: The component is already constrained and reinforcement follows only after a bridge period. | The measured exceedance consists of short episodes, improving the fit of targeted storage dispatch. | Collective initiatives are at an early stage and are primarily focused on knowledge exchange. | Q33: Walcheren|Timing, duration, reliability and predictability
A34: Schouwen-Duiveland | B34: Grid operator | C34: Timing, duration, reliability and predictability | D34: Group Transport Agreement | E34: 0 | F34: Base score unchanged for this case. | G34: Base TAPIR assessment | H34: Schouwen-Duiveland|Grid operator|Timing, duration, reliability and predictability|Group Transport Agreement | I34: =INDEX($F$6:$I$15,MATCH($C34,$B$6:$B$15,0),MATCH($D34,$F$5:$I$5,0)) -> 3 | J34: =INDEX($C$6:$C$15,MATCH($C34,$B$6:$B$15,0)) -> 0.2 | K34: =MAX(1,MIN(5,I34+E34)) -> 3 | L34: =J34*K34 -> 0.6 | N34: Walcheren | O34: Speed and effect on reinforcement bridge gap | P34: The battery test clears the 90% threshold during the available bridge period. | No intervention leaves the measured ATC stress at 94.8% throughout the bridge period. | Q34: Walcheren|Speed and effect on reinforcement bridge gap
A35: Schouwen-Duiveland | B35: Grid operator | C35: Timing, duration, reliability and predictability | D35: No additional intervention | E35: 0 | F35: Base score unchanged for this case. | G35: Base TAPIR assessment | H35: Schouwen-Duiveland|Grid operator|Timing, duration, reliability and predictability|No additional intervention | I35: =INDEX($F$6:$I$15,MATCH($C35,$B$6:$B$15,0),MATCH($D35,$F$5:$I$5,0)) -> 1 | J35: =INDEX($C$6:$C$15,MATCH($C35,$B$6:$B$15,0)) -> 0.2 | K35: =MAX(1,MIN(5,I35+E35)) -> 1 | L35: =J35*K35 -> 0.2 | N35: Walcheren | O35: Technical and operational readiness | P35: Several companies already operate batteries with an Energy Management System. | Q35: Walcheren|Technical and operational readiness
A36: Schouwen-Duiveland | B36: Grid operator | C36: Speed and effect on reinforcement bridge gap | D36: Conventional grid reinforcement | E36: 0 | F36: Base score unchanged for this case. | G36: Base TAPIR assessment | H36: Schouwen-Duiveland|Grid operator|Speed and effect on reinforcement bridge gap|Conventional grid reinforcement | I36: =INDEX($F$6:$I$15,MATCH($C36,$B$6:$B$15,0),MATCH($D36,$F$5:$I$5,0)) -> 1 | J36: =INDEX($C$6:$C$15,MATCH($C36,$B$6:$B$15,0)) -> 0.2 | K36: =MAX(1,MIN(5,I36+E36)) -> 1 | L36: =J36*K36 -> 0.2 | N36: Walcheren | O36: Legal, contractual and policy embeddedness | P36: Base score unchanged for this criterion. | Q36: Walcheren|Legal, contractual and policy embeddedness
A37: Schouwen-Duiveland | B37: Grid operator | C37: Speed and effect on reinforcement bridge gap | D37: Battery + EMS | E37: 0 | F37: Base score unchanged for this case. | G37: Base TAPIR assessment | H37: Schouwen-Duiveland|Grid operator|Speed and effect on reinforcement bridge gap|Battery + EMS | I37: =INDEX($F$6:$I$15,MATCH($C37,$B$6:$B$15,0),MATCH($D37,$F$5:$I$5,0)) -> 5 | J37: =INDEX($C$6:$C$15,MATCH($C37,$B$6:$B$15,0)) -> 0.2 | K37: =MAX(1,MIN(5,I37+E37)) -> 5 | L37: =J37*K37 -> 1 | N37: Walcheren | O37: Financial attractiveness | P37: Companies view the option more favourably where it is cost-neutral and delivers usable connection capacity. | The arrangement can reduce stress without requiring company-owned grid infrastructure. | Q37: Walcheren|Financial attractiveness
A38: Schouwen-Duiveland | B38: Grid operator | C38: Speed and effect on reinforcement bridge gap | D38: Group Transport Agreement | E38: 0 | F38: Base score unchanged for this case. | G38: Base TAPIR assessment | H38: Schouwen-Duiveland|Grid operator|Speed and effect on reinforcement bridge gap|Group Transport Agreement | I38: =INDEX($F$6:$I$15,MATCH($C38,$B$6:$B$15,0),MATCH($D38,$F$5:$I$5,0)) -> 3 | J38: =INDEX($C$6:$C$15,MATCH($C38,$B$6:$B$15,0)) -> 0.2 | K38: =MAX(1,MIN(5,I38+E38)) -> 3 | L38: =J38*K38 -> 0.6 | N38: Walcheren | O38: Implementation speed and urgency fit | P38: The solution can be implemented within the bridge period. | Q38: Walcheren|Implementation speed and urgency fit
A39: Schouwen-Duiveland | B39: Grid operator | C39: Speed and effect on reinforcement bridge gap | D39: No additional intervention | E39: -0.5 | F39: No relief is provided during the bridge period; the baseline ATC stress remains 97.0%. | G39: Percentage-based grid assessment | H39: Schouwen-Duiveland|Grid operator|Speed and effect on reinforcement bridge gap|No additional intervention | I39: =INDEX($F$6:$I$15,MATCH($C39,$B$6:$B$15,0),MATCH($D39,$F$5:$I$5,0)) -> 2 | J39: =INDEX($C$6:$C$15,MATCH($C39,$B$6:$B$15,0)) -> 0.2 | K39: =MAX(1,MIN(5,I39+E39)) -> 1.5 | L39: =J39*K39 -> 0.3 | N39: Walcheren | O39: Knowledge and organisational burden | P39: Battery and EMS operation is already established locally. | Collective implementation is company-led, placing coordination work on participating companies. | Q39: Walcheren|Knowledge and organisational burden
... A51: Schouwen-Duiveland | B51: Company | C51: Financial attractiveness | D51: No additional intervention | E51: 0 | F51: Base score unchanged for this case. | G51: Base TAPIR assessment | H51: Schouwen-Duiveland|Company|Financial attractiveness|No additional intervention | I51: =INDEX($F$6:$I$15,MATCH($C51,$B$6:$B$15,0),MATCH($D51,$F$5:$I$5,0)) -> 2 | J51: =INDEX($C$6:$C$15,MATCH($C51,$B$6:$B$15,0)) -> 0.3 | K51: =MAX(1,MIN(5,I51+E51)) -> 2 | L51: =J51*K51 -> 0.6 | N51: West-Zeeuws-Vlaanderen | O51: Sustainability, image and strategic risk | P51: Base score unchanged for this criterion. | Q51: West-Zeeuws-Vlaanderen|Sustainability, image and strategic risk
A52: Schouwen-Duiveland | B52: Company | C52: Implementation speed and urgency fit | D52: Conventional grid reinforcement | E52: 0 | F52: Base score unchanged for this case. | G52: Base TAPIR assessment | H52: Schouwen-Duiveland|Company|Implementation speed and urgency fit|Conventional grid reinforcement | I52: =INDEX($F$6:$I$15,MATCH($C52,$B$6:$B$15,0),MATCH($D52,$F$5:$I$5,0)) -> 1 | J52: =INDEX($C$6:$C$15,MATCH($C52,$B$6:$B$15,0)) -> 0.2 | K52: =MAX(1,MIN(5,I52+E52)) -> 1 | L52: =J52*K52 -> 0.2
A53: Schouwen-Duiveland | B53: Company | C53: Implementation speed and urgency fit | D53: Battery + EMS | E53: 0 | F53: Base score unchanged for this case. | G53: Base TAPIR assessment | H53: Schouwen-Duiveland|Company|Implementation speed and urgency fit|Battery + EMS | I53: =INDEX($F$6:$I$15,MATCH($C53,$B$6:$B$15,0),MATCH($D53,$F$5:$I$5,0)) -> 4 | J53: =INDEX($C$6:$C$15,MATCH($C53,$B$6:$B$15,0)) -> 0.2 | K53: =MAX(1,MIN(5,I53+E53)) -> 4 | L53: =J53*K53 -> 0.8
A54: Schouwen-Duiveland | B54: Company | C54: Implementation speed and urgency fit | D54: Group Transport Agreement | E54: 0 | F54: Base score unchanged for this case. | G54: Base TAPIR assessment | H54: Schouwen-Duiveland|Company|Implementation speed and urgency fit|Group Transport Agreement | I54: =INDEX($F$6:$I$15,MATCH($C54,$B$6:$B$15,0),MATCH($D54,$F$5:$I$5,0)) -> 3 | J54: =INDEX($C$6:$C$15,MATCH($C54,$B$6:$B$15,0)) -> 0.2 | K54: =MAX(1,MIN(5,I54+E54)) -> 3 | L54: =J54*K54 -> 0.6 | N54: Scoring rules | O54: Scoring rules | P54: Scoring rules | Q54: Scoring rules | R54: Scoring rules | S54: Scoring rules | T54: Scoring rules
...

Sheet Read Me
A1: Read Me — Public TAPIR Decision-Support Tool | B1: Read Me — Public TAPIR Decision-Support Tool | C1: Read Me — Public TAPIR Decision-Support Tool | D1: Read Me — Public TAPIR Decision-Support Tool | E1: Read Me — Public TAPIR Decision-Support Tool | F1: Read Me — Public TAPIR Decision-Support Tool | G1: Read Me — Public TAPIR Decision-Support Tool | H1: Read Me — Public TAPIR Decision-Support Tool
A2: This clean public workbook preserves the decision-support logic while removing confidential grid-operator asset and load information. | B2: This clean public workbook preserves the decision-support logic while removing confidential grid-operator asset and load information. | C2: This clean public workbook preserves the decision-support logic while removing confidential grid-operator asset and load information. | D2: This clean public workbook preserves the decision-support logic while removing confidential grid-operator asset and load information. | E2: This clean public workbook preserves the decision-support logic while removing confidential grid-operator asset and load information. | F2: This clean public workbook preserves the decision-support logic while removing confidential grid-operator asset and load information. | G2: This clean public workbook preserves the decision-support logic while removing confidential grid-operator asset and load information. | H2: This clean public workbook preserves the decision-support logic while removing confidential grid-operator asset and load information.
A4: How to use | B4: How to use | C4: How to use | D4: How to use | E4: How to use | F4: How to use | G4: How to use | H4: How to use
A5: 1. Open the Public Tool sheet and select one of the three case regions in the yellow case selector.
A6: 2. Review the four response-option scores, the percentage-based grid assessment and the case-specific evidence.
A7: 3. If sensitivity testing is required, edit only the yellow weight, base-score and regional-adjustment cells on Public Inputs.
A9: Terminology used | B9: Terminology used | C9: Terminology used | D9: Terminology used | E9: Terminology used | F9: Terminology used | G9: Terminology used | H9: Terminology used
A10: Response option is the umbrella term for the alternatives assessed by the tool: conventional grid reinforcement, battery + EMS, Group Transport Agreement and no additional intervention.
A11: Flexibility solutions are the response-option subset that uses demand, generation or storage flexibility within available grid capacity: battery + EMS and the Group Transport Agreement.
A12: Grid reinforcement is not a flexibility solution. No additional intervention is the reference response option.
A14: Public anonymisation applied | B14: Public anonymisation applied | C14: Public anonymisation applied | D14: Public anonymisation applied | E14: Public anonymisation applied | F14: Public anonymisation applied | G14: Public anonymisation applied | H14: Public anonymisation applied
A15: The three village names have been replaced by the non-identifying labels Village 1, Village 2 and Village 3.
A16: All station names, abbreviations, codes, addresses and connected-asset identifiers have been removed and replaced by generic grid-component descriptions.
A17: All absolute load, energy, capacity and relief values have been removed. The retained grid indicators are percentages of available transport capacity (ATC).
A18: Exact reinforcement costs, capacities and dates, internal source filenames and recoverable raw-data tables have been removed.
A19: The workbook has no hidden worksheets, external links, charts linked to confidential data or embedded source files.
A21: Evidence retained | B21: Evidence retained | C21: Evidence retained | D21: Evidence retained | E21: Evidence retained | F21: Evidence retained | G21: Evidence retained | H21: Evidence retained
A22: General case findings from the thesis and interviews are retained where they explain maturity, coordination, authority, organisational burden and company preferences.
A23: Grid evidence is retained only in normalised percentage form and is labelled as measured, forecast or uncertain.
A24: No new interview evidence or literature has been introduced.
A26: Limitations | B26: Limitations | C26: Limitations | D26: Limitations | E26: Limitations | F26: Limitations | G26: Limitations | H26: Limitations
A27: The public percentages support comparison but cannot reproduce the grid operator's internal calculations because the absolute source data have deliberately been removed.
A28: A preferred response option is a decision-support result, not an automatic investment decision. Local engineering validation, legal assessment and actor agreement remain necessary.
