Workbook

Sheet Public Tool
A1: TAPIR Public Decision-Support Tool
A2: Select a case to see the preferred pathway, actor scores and the essential evidence at a glance
A3: SELECTED CASE | C3: Walcheren
A4: Response-option ranking | H4: Preferred response option
A5: Response option | D5: Stedin | E5: Company | F5: Equal actor average | H5: =INDEX($A$6:$A$9,MATCH(MAX($F$6:$F$9),$F$6:$F$9,0)) -> Battery + EMS
A6: Conventional grid reinforcement | D6: =SUMIFS('Public Inputs'!$P$6:$P$17,'Public Inputs'!$N$6:$N$17,$C$3,'Public Inputs'!$O$6:$O$17,$A6) -> 2.85 | E6: =SUMIFS('Public Inputs'!$Q$6:$Q$17,'Public Inputs'!$N$6:$N$17,$C$3,'Public Inputs'!$O$6:$O$17,$A6) -> 2.5 | F6: =SUMIFS('Public Inputs'!$R$6:$R$17,'Public Inputs'!$N$6:$N$17,$C$3,'Public Inputs'!$O$6:$O$17,$A6) -> 2.675
A7: Battery + EMS | D7: =SUMIFS('Public Inputs'!$P$6:$P$17,'Public Inputs'!$N$6:$N$17,$C$3,'Public Inputs'!$O$6:$O$17,$A7) -> 3.975 | E7: =SUMIFS('Public Inputs'!$Q$6:$Q$17,'Public Inputs'!$N$6:$N$17,$C$3,'Public Inputs'!$O$6:$O$17,$A7) -> 4.45 | F7: =SUMIFS('Public Inputs'!$R$6:$R$17,'Public Inputs'!$N$6:$N$17,$C$3,'Public Inputs'!$O$6:$O$17,$A7) -> 4.2125 | H7: ="Grid operator "&TEXT(INDEX($D$6:$D$9,MATCH($H$5,$A$6:$A$9,0)),"0.0")&" / 5 | Company "&TEXT(INDEX($E$6:$E$9,MATCH($H$5,$A$6:$A$9,0)),"0.0")&" / 5 | Overall "&TEXT(INDEX($F$6:$F$9,MATCH($H$5,$A$6:$A$9,0)),"0.0")&" / 5" -> Grid operator 04 / 5 | Company 04 / 5 | Overall 04 / 5
A8: Group Transport Agreement | D8: =SUMIFS('Public Inputs'!$P$6:$P$17,'Public Inputs'!$N$6:$N$17,$C$3,'Public Inputs'!$O$6:$O$17,$A8) -> 3.05 | E8: =SUMIFS('Public Inputs'!$Q$6:$Q$17,'Public Inputs'!$N$6:$N$17,$C$3,'Public Inputs'!$O$6:$O$17,$A8) -> 3.3 | F8: =SUMIFS('Public Inputs'!$R$6:$R$17,'Public Inputs'!$N$6:$N$17,$C$3,'Public Inputs'!$O$6:$O$17,$A8) -> 3.175 | H8: =INDEX('Public Inputs'!$K$22:$K$24,MATCH($C$3,'Public Inputs'!$A$22:$A$24,0)) -> Short peaks at the high-voltage station are reduced below the threshold by both flexibility solutions. The margins are narrow, and performance over the full period remains uncertain without a forward series.
A9: No additional intervention | D9: =SUMIFS('Public Inputs'!$P$6:$P$17,'Public Inputs'!$N$6:$N$17,$C$3,'Public Inputs'!$O$6:$O$17,$A9) -> 3.05 | E9: =SUMIFS('Public Inputs'!$Q$6:$Q$17,'Public Inputs'!$N$6:$N$17,$C$3,'Public Inputs'!$O$6:$O$17,$A9) -> 2.7 | F9: =SUMIFS('Public Inputs'!$R$6:$R$17,'Public Inputs'!$N$6:$N$17,$C$3,'Public Inputs'!$O$6:$O$17,$A9) -> 2.875
A11: Case context - public village demand indicators and percentage-only station load
A12: Public village label | C12: Village data coverage | E12: Average daily demand | G12: Village maximum peak | I12: Peak period at annual maximum | K12: Peak-period average
A13: =INDEX('Public Inputs'!$B$22:$B$24,MATCH($C$3,'Public Inputs'!$A$22:$A$24,0)) -> Village 2 | C13: =INDEX('Public Inputs'!$V$22:$V$24,MATCH($C$3,'Public Inputs'!$A$22:$A$24,0)) -> 1 | E13: =INDEX('Public Inputs'!$W$22:$W$24,MATCH($C$3,'Public Inputs'!$A$22:$A$24,0)) -> 29171.2 | G13: =INDEX('Public Inputs'!$X$22:$X$24,MATCH($C$3,'Public Inputs'!$A$22:$A$24,0)) -> 3644.4 | I13: =INDEX('Public Inputs'!$Y$22:$Y$24,MATCH($C$3,'Public Inputs'!$A$22:$A$24,0)) -> Christmas holiday | K13: =INDEX('Public Inputs'!$Z$22:$Z$24,MATCH($C$3,'Public Inputs'!$A$22:$A$24,0)) -> 48505.2
A14: Grid level | C14: ATC stress 2025 | E14: ATC stress 2031 | G14: First constraint year | I14: Hours at or above 90% (total / holiday) | K14: Holiday share of those hours
A15: Distribution / MS level | C15: =INDEX('Public Inputs'!$AA$22:$AA$24,MATCH($C$3,'Public Inputs'!$A$22:$A$24,0)) -> 0.634 | E15: =INDEX('Public Inputs'!$AB$22:$AB$24,MATCH($C$3,'Public Inputs'!$A$22:$A$24,0)) -> 0.823 | G15: =INDEX('Public Inputs'!$AC$22:$AC$24,MATCH($C$3,'Public Inputs'!$A$22:$A$24,0)) -> 2035 | I15: =INDEX('Public Inputs'!$AD$22:$AD$24,MATCH($C$3,'Public Inputs'!$A$22:$A$24,0)) -> 0 total / 0 holiday | K15: =INDEX('Public Inputs'!$AE$22:$AE$24,MATCH($C$3,'Public Inputs'!$A$22:$A$24,0)) -> N/A
A16: Main Distribution Station level | C16: =INDEX('Public Inputs'!$AF$22:$AF$24,MATCH($C$3,'Public Inputs'!$A$22:$A$24,0)) -> 0.948 | E16: =INDEX('Public Inputs'!$AG$22:$AG$24,MATCH($C$3,'Public Inputs'!$A$22:$A$24,0)) -> >100% | G16: =INDEX('Public Inputs'!$AH$22:$AH$24,MATCH($C$3,'Public Inputs'!$A$22:$A$24,0)) -> 2025 | I16: =INDEX('Public Inputs'!$AI$22:$AI$24,MATCH($C$3,'Public Inputs'!$A$22:$A$24,0)) -> 4.25 total / 1.75 holiday | K16: =INDEX('Public Inputs'!$AJ$22:$AJ$24,MATCH($C$3,'Public Inputs'!$A$22:$A$24,0)) -> 0.412
A17: Threshold 90% | C17: =INDEX('Public Inputs'!$J$22:$J$24,MATCH($C$3,'Public Inputs'!$A$22:$A$24,0)) -> Both flexibility solutions clear the 90% threshold in the measured test
A18: =INDEX('Public Inputs'!$AK$22:$AK$24,MATCH($C$3,'Public Inputs'!$A$22:$A$24,0)) -> The high-voltage percentage is a 2025 measurement; no forward forecast series exists for that level because reinforcement follows in the short term. The distribution-level percentage is the 2031 forecast. Flexibility lowers the high-voltage level to 88.3% (battery + EMS) and 89.1% (Group Transport Agreement).
A20: TAPIR-adjusted criteria and selected-case scores
A21: Actor | B21: Criterion | D21: Weight | E21: TAPIR factor | F21: Conventional grid reinforcement | G21: Battery + EMS | H21: Group Transport Agreement | I21: No additional intervention | J21: KPI / evidence applied | L21: Case specific adjustments
A22: Grid operator | B22: Grid-operator life-cycle cost and investment effect | D22: =INDEX('Public Inputs'!$C$6:$C$15,MATCH($B22,'Public Inputs'!$B$6:$B$15,0)) -> 0.3 | E22: =INDEX('Public Inputs'!$D$6:$D$15,MATCH($B22,'Public Inputs'!$B$6:$B$15,0)) -> Economic prospects | F22: =SUMIFS('Public Inputs'!$K$28:$K$147,'Public Inputs'!$A$28:$A$147,$C$3,'Public Inputs'!$B$28:$B$147,$A22,'Public Inputs'!$C$28:$C$147,$B22,'Public Inputs'!$D$28:$D$147,F$21) -> 2 | G22: =SUMIFS('Public Inputs'!$K$28:$K$147,'Public Inputs'!$A$28:$A$147,$C$3,'Public Inputs'!$B$28:$B$147,$A22,'Public Inputs'!$C$28:$C$147,$B22,'Public Inputs'!$D$28:$D$147,G$21) -> 4.5 | H22: =SUMIFS('Public Inputs'!$K$28:$K$147,'Public Inputs'!$A$28:$A$147,$C$3,'Public Inputs'!$B$28:$B$147,$A22,'Public Inputs'!$C$28:$C$147,$B22,'Public Inputs'!$D$28:$D$147,H$21) -> 4.5 | I22: =SUMIFS('Public Inputs'!$K$28:$K$147,'Public Inputs'!$A$28:$A$147,$C$3,'Public Inputs'!$B$28:$B$147,$A22,'Public Inputs'!$C$28:$C$147,$B22,'Public Inputs'!$D$28:$D$147,I$21) -> 5 | J22: Reinforcement investment cost (EUR), identified flexibility cost and years of deferred reinforcement investment; no complete discounted life-cycle cost | L22: =IFERROR(CHOOSE(MATCH($C$3,{"Schouwen-Duiveland","Walcheren","West-Zeeuws-Vlaanderen"},0),"","Battery +0.5 — clears the threshold: ATC 0.948 → 0.883. | GTO +0.5 — clears the threshold: ATC 0.948 → 0.891.","Battery +0.5 — clears the threshold: ATC 0.906 → 0.861. | GTO +0.5 — clears the threshold: ATC 0.906 → 0.858."),"") -> Battery +0.5 — clears the threshold: ATC 0.948 → 0.883. | GTO +0.5 — clears the threshold: ATC 0.948 → 0.891.
A23: Grid operator | B23: Timing, duration, reliability and predictability | D23: =INDEX('Public Inputs'!$C$6:$C$15,MATCH($B23,'Public Inputs'!$B$6:$B$15,0)) -> 0.2 | E23: =INDEX('Public Inputs'!$D$6:$D$15,MATCH($B23,'Public Inputs'!$B$6:$B$15,0)) -> Maturity | F23: =SUMIFS('Public Inputs'!$K$28:$K$147,'Public Inputs'!$A$28:$A$147,$C$3,'Public Inputs'!$B$28:$B$147,$A23,'Public Inputs'!$C$28:$C$147,$B23,'Public Inputs'!$D$28:$D$147,F$21) -> 3.5 | G23: =SUMIFS('Public Inputs'!$K$28:$K$147,'Public Inputs'!$A$28:$A$147,$C$3,'Public Inputs'!$B$28:$B$147,$A23,'Public Inputs'!$C$28:$C$147,$B23,'Public Inputs'!$D$28:$D$147,G$21) -> 2.5 | H23: =SUMIFS('Public Inputs'!$K$28:$K$147,'Public Inputs'!$A$28:$A$147,$C$3,'Public Inputs'!$B$28:$B$147,$A23,'Public Inputs'!$C$28:$C$147,$B23,'Public Inputs'!$D$28:$D$147,H$21) -> 2.5 | I23: =SUMIFS('Public Inputs'!$K$28:$K$147,'Public Inputs'!$A$28:$A$147,$C$3,'Public Inputs'!$B$28:$B$147,$A23,'Public Inputs'!$C$28:$C$147,$B23,'Public Inputs'!$D$28:$D$147,I$21) -> 1 | J23: Critical hours, holiday overlap, availability, asset life | L23: =IFERROR(CHOOSE(MATCH($C$3,{"Schouwen-Duiveland","Walcheren","West-Zeeuws-Vlaanderen"},0),"Grid −0.5 — reinforcement only July 2032; 10 h above 0.90 in 2031.","Grid −0.5 — constrained since 2025; reinforcement only end 2028. | Battery +0.5 — stress in 4.25 h a year, episodes of about one hour. | GTO −0.5 — collective maturity 2 of 5; initiatives are knowledge exchange only.","Grid −0.5 — the 2028 intervention is not attributed to this component. | GTO −0.5 — collective maturity 1 of 5; chain parks are centrally controlled."),"") -> Grid −0.5 — constrained since 2025; reinforcement only end 2028. | Battery +0.5 — stress in 4.25 h a year, episodes of about one hour. | GTO −0.5 — collective maturity 2 of 5; initiatives are knowledge exchange only.
A24: Grid operator | B24: Speed and effect on reinforcement bridge gap | D24: =INDEX('Public Inputs'!$C$6:$C$15,MATCH($B24,'Public Inputs'!$B$6:$B$15,0)) -> 0.2 | E24: =INDEX('Public Inputs'!$D$6:$D$15,MATCH($B24,'Public Inputs'!$B$6:$B$15,0)) -> Feasibility | F24: =SUMIFS('Public Inputs'!$K$28:$K$147,'Public Inputs'!$A$28:$A$147,$C$3,'Public Inputs'!$B$28:$B$147,$A24,'Public Inputs'!$C$28:$C$147,$B24,'Public Inputs'!$D$28:$D$147,F$21) -> 1 | G24: =SUMIFS('Public Inputs'!$K$28:$K$147,'Public Inputs'!$A$28:$A$147,$C$3,'Public Inputs'!$B$28:$B$147,$A24,'Public Inputs'!$C$28:$C$147,$B24,'Public Inputs'!$D$28:$D$147,G$21) -> 5 | H24: =SUMIFS('Public Inputs'!$K$28:$K$147,'Public Inputs'!$A$28:$A$147,$C$3,'Public Inputs'!$B$28:$B$147,$A24,'Public Inputs'!$C$28:$C$147,$B24,'Public Inputs'!$D$28:$D$147,H$21) -> 3 | I24: =SUMIFS('Public Inputs'!$K$28:$K$147,'Public Inputs'!$A$28:$A$147,$C$3,'Public Inputs'!$B$28:$B$147,$A24,'Public Inputs'!$C$28:$C$147,$B24,'Public Inputs'!$D$28:$D$147,I$21) -> 1.5 | J24: Constraint year, reinforcement year, bridge period, station peak relief, ATC <= 0.90 and years actually bridged | L24: =IFERROR(CHOOSE(MATCH($C$3,{"Schouwen-Duiveland","Walcheren","West-Zeeuws-Vlaanderen"},0),"Exit −0.5 — no relief; ATC stays 0.970 through the 1-year bridge period.","Battery +0.5 — clears 0.90 and covers 3 of the 3 bridge years. | Exit −0.5 — peak stays at 0.948 for all three years.","Battery +0.5 — clears 0.90 with the widest margin, 0.042. | Exit −0.5 — forecast exceeds capacity in 2029 with no dated reinforcement."),"") -> Battery +0.5 — clears 0.90 and covers 3 of the 3 bridge years. | Exit −0.5 — peak stays at 0.948 for all three years.
A25: Grid operator | B25: Technical and operational readiness | D25: =INDEX('Public Inputs'!$C$6:$C$15,MATCH($B25,'Public Inputs'!$B$6:$B$15,0)) -> 0.15 | E25: =INDEX('Public Inputs'!$D$6:$D$15,MATCH($B25,'Public Inputs'!$B$6:$B$15,0)) -> Maturity | F25: =SUMIFS('Public Inputs'!$K$28:$K$147,'Public Inputs'!$A$28:$A$147,$C$3,'Public Inputs'!$B$28:$B$147,$A25,'Public Inputs'!$C$28:$C$147,$B25,'Public Inputs'!$D$28:$D$147,F$21) -> 5 | G25: =SUMIFS('Public Inputs'!$K$28:$K$147,'Public Inputs'!$A$28:$A$147,$C$3,'Public Inputs'!$B$28:$B$147,$A25,'Public Inputs'!$C$28:$C$147,$B25,'Public Inputs'!$D$28:$D$147,G$21) -> 4.5 | H25: =SUMIFS('Public Inputs'!$K$28:$K$147,'Public Inputs'!$A$28:$A$147,$C$3,'Public Inputs'!$B$28:$B$147,$A25,'Public Inputs'!$C$28:$C$147,$B25,'Public Inputs'!$D$28:$D$147,H$21) -> 2 | I25: =SUMIFS('Public Inputs'!$K$28:$K$147,'Public Inputs'!$A$28:$A$147,$C$3,'Public Inputs'!$B$28:$B$147,$A25,'Public Inputs'!$C$28:$C$147,$B25,'Public Inputs'!$D$28:$D$147,I$21) -> 2 | J25: Battery/EMS installed, control systems, GTO status | L25: =IFERROR(CHOOSE(MATCH($C$3,{"Schouwen-Duiveland","Walcheren","West-Zeeuws-Vlaanderen"},0),"GTO +0.5 — energy cooperation developing towards hubs and GTOs; collective maturity 4 of 5.","Battery +0.5 — several companies already operate batteries with EMS.","GTO −0.5 — no operating collective arrangement in the case."),"") -> Battery +0.5 — several companies already operate batteries with EMS.
A26: Grid operator | B26: Legal, contractual and policy embeddedness | D26: =INDEX('Public Inputs'!$C$6:$C$15,MATCH($B26,'Public Inputs'!$B$6:$B$15,0)) -> 0.15 | E26: =INDEX('Public Inputs'!$D$6:$D$15,MATCH($B26,'Public Inputs'!$B$6:$B$15,0)) -> Local embeddedness | F26: =SUMIFS('Public Inputs'!$K$28:$K$147,'Public Inputs'!$A$28:$A$147,$C$3,'Public Inputs'!$B$28:$B$147,$A26,'Public Inputs'!$C$28:$C$147,$B26,'Public Inputs'!$D$28:$D$147,F$21) -> 4 | G26: =SUMIFS('Public Inputs'!$K$28:$K$147,'Public Inputs'!$A$28:$A$147,$C$3,'Public Inputs'!$B$28:$B$147,$A26,'Public Inputs'!$C$28:$C$147,$B26,'Public Inputs'!$D$28:$D$147,G$21) -> 3 | H26: =SUMIFS('Public Inputs'!$K$28:$K$147,'Public Inputs'!$A$28:$A$147,$C$3,'Public Inputs'!$B$28:$B$147,$A26,'Public Inputs'!$C$28:$C$147,$B26,'Public Inputs'!$D$28:$D$147,H$21) -> 2 | I26: =SUMIFS('Public Inputs'!$K$28:$K$147,'Public Inputs'!$A$28:$A$147,$C$3,'Public Inputs'!$B$28:$B$147,$A26,'Public Inputs'!$C$28:$C$147,$B26,'Public Inputs'!$D$28:$D$147,I$21) -> 5 | J26: Legal status, agreements, connection conditions, policy alignment | L26: =IFERROR(CHOOSE(MATCH($C$3,{"Schouwen-Duiveland","Walcheren","West-Zeeuws-Vlaanderen"},0),"","",""),"")
A27: Company | B27: Financial attractiveness | D27: =INDEX('Public Inputs'!$C$6:$C$15,MATCH($B27,'Public Inputs'!$B$6:$B$15,0)) -> 0.3 | E27: =INDEX('Public Inputs'!$D$6:$D$15,MATCH($B27,'Public Inputs'!$B$6:$B$15,0)) -> Economic prospects | F27: =SUMIFS('Public Inputs'!$K$28:$K$147,'Public Inputs'!$A$28:$A$147,$C$3,'Public Inputs'!$B$28:$B$147,$A27,'Public Inputs'!$C$28:$C$147,$B27,'Public Inputs'!$D$28:$D$147,F$21) -> 2 | G27: =SUMIFS('Public Inputs'!$K$28:$K$147,'Public Inputs'!$A$28:$A$147,$C$3,'Public Inputs'!$B$28:$B$147,$A27,'Public Inputs'!$C$28:$C$147,$B27,'Public Inputs'!$D$28:$D$147,G$21) -> 5 | H27: =SUMIFS('Public Inputs'!$K$28:$K$147,'Public Inputs'!$A$28:$A$147,$C$3,'Public Inputs'!$B$28:$B$147,$A27,'Public Inputs'!$C$28:$C$147,$B27,'Public Inputs'!$D$28:$D$147,H$21) -> 4.5 | I27: =SUMIFS('Public Inputs'!$K$28:$K$147,'Public Inputs'!$A$28:$A$147,$C$3,'Public Inputs'!$B$28:$B$147,$A27,'Public Inputs'!$C$28:$C$147,$B27,'Public Inputs'!$D$28:$D$147,I$21) -> 2 | J27: Cost, annual benefit, payback, grid charges, GTO compensation | L27: =IFERROR(CHOOSE(MATCH($C$3,{"Schouwen-Duiveland","Walcheren","West-Zeeuws-Vlaanderen"},0),"","Battery +0.5 — payback accepted where cost-neutral and capacity is delivered. | GTO +0.5 — clears the threshold without company capital expenditure.","Battery +0.5 — batteries already under consideration by companies. | GTO +0.5 — clears the threshold without company capital expenditure."),"") -> Battery +0.5 — payback accepted where cost-neutral and capacity is delivered. | GTO +0.5 — clears the threshold without company capital expenditure.
A28: Company | B28: Implementation speed and urgency fit | D28: =INDEX('Public Inputs'!$C$6:$C$15,MATCH($B28,'Public Inputs'!$B$6:$B$15,0)) -> 0.2 | E28: =INDEX('Public Inputs'!$D$6:$D$15,MATCH($B28,'Public Inputs'!$B$6:$B$15,0)) -> Feasibility | F28: =SUMIFS('Public Inputs'!$K$28:$K$147,'Public Inputs'!$A$28:$A$147,$C$3,'Public Inputs'!$B$28:$B$147,$A28,'Public Inputs'!$C$28:$C$147,$B28,'Public Inputs'!$D$28:$D$147,F$21) -> 1 | G28: =SUMIFS('Public Inputs'!$K$28:$K$147,'Public Inputs'!$A$28:$A$147,$C$3,'Public Inputs'!$B$28:$B$147,$A28,'Public Inputs'!$C$28:$C$147,$B28,'Public Inputs'!$D$28:$D$147,G$21) -> 4.5 | H28: =SUMIFS('Public Inputs'!$K$28:$K$147,'Public Inputs'!$A$28:$A$147,$C$3,'Public Inputs'!$B$28:$B$147,$A28,'Public Inputs'!$C$28:$C$147,$B28,'Public Inputs'!$D$28:$D$147,H$21) -> 3 | I28: =SUMIFS('Public Inputs'!$K$28:$K$147,'Public Inputs'!$A$28:$A$147,$C$3,'Public Inputs'!$B$28:$B$147,$A28,'Public Inputs'!$C$28:$C$147,$B28,'Public Inputs'!$D$28:$D$147,I$21) -> 1 | J28: Constraint year, reinforcement date, case-specific lead time and availability before the constraint | L28: =IFERROR(CHOOSE(MATCH($C$3,{"Schouwen-Duiveland","Walcheren","West-Zeeuws-Vlaanderen"},0),"","Battery +0.5 — available well before the end of 2028.","Battery +0.5 — available before any reinforcement, which is undated here."),"") -> Battery +0.5 — available well before the end of 2028.
A29: Company | B29: Knowledge and organisational burden | D29: =INDEX('Public Inputs'!$C$6:$C$15,MATCH($B29,'Public Inputs'!$B$6:$B$15,0)) -> 0.2 | E29: =INDEX('Public Inputs'!$D$6:$D$15,MATCH($B29,'Public Inputs'!$B$6:$B$15,0)) -> Scalability + feasibility | F29: =SUMIFS('Public Inputs'!$K$28:$K$147,'Public Inputs'!$A$28:$A$147,$C$3,'Public Inputs'!$B$28:$B$147,$A29,'Public Inputs'!$C$28:$C$147,$B29,'Public Inputs'!$D$28:$D$147,F$21) -> 4 | G29: =SUMIFS('Public Inputs'!$K$28:$K$147,'Public Inputs'!$A$28:$A$147,$C$3,'Public Inputs'!$B$28:$B$147,$A29,'Public Inputs'!$C$28:$C$147,$B29,'Public Inputs'!$D$28:$D$147,G$21) -> 3.5 | H29: =SUMIFS('Public Inputs'!$K$28:$K$147,'Public Inputs'!$A$28:$A$147,$C$3,'Public Inputs'!$B$28:$B$147,$A29,'Public Inputs'!$C$28:$C$147,$B29,'Public Inputs'!$D$28:$D$147,H$21) -> 1.5 | I29: =SUMIFS('Public Inputs'!$K$28:$K$147,'Public Inputs'!$A$28:$A$147,$C$3,'Public Inputs'!$B$28:$B$147,$A29,'Public Inputs'!$C$28:$C$147,$B29,'Public Inputs'!$D$28:$D$147,I$21) -> 5 | J29: Advice needed, actors involved, management time, coordination | L29: =IFERROR(CHOOSE(MATCH($C$3,{"Schouwen-Duiveland","Walcheren","West-Zeeuws-Vlaanderen"},0),"GTO +0.5 — regional groups and proactive municipal facilitation lower the coordination burden.","Battery +0.5 — battery and EMS operation already established locally. | GTO −0.5 — collective work is company-led; coordination falls on the companies.","GTO −0.5 — requires new cooperation and governance that is absent."),"") -> Battery +0.5 — battery and EMS operation already established locally. | GTO −0.5 — collective work is company-led; coordination falls on the companies.
A30: Company | B30: Autonomy and dependency | D30: =INDEX('Public Inputs'!$C$6:$C$15,MATCH($B30,'Public Inputs'!$B$6:$B$15,0)) -> 0.15 | E30: =INDEX('Public Inputs'!$D$6:$D$15,MATCH($B30,'Public Inputs'!$B$6:$B$15,0)) -> Regional relatedness + local embeddedness | F30: =SUMIFS('Public Inputs'!$K$28:$K$147,'Public Inputs'!$A$28:$A$147,$C$3,'Public Inputs'!$B$28:$B$147,$A30,'Public Inputs'!$C$28:$C$147,$B30,'Public Inputs'!$D$28:$D$147,F$21) -> 3 | G30: =SUMIFS('Public Inputs'!$K$28:$K$147,'Public Inputs'!$A$28:$A$147,$C$3,'Public Inputs'!$B$28:$B$147,$A30,'Public Inputs'!$C$28:$C$147,$B30,'Public Inputs'!$D$28:$D$147,G$21) -> 5 | H30: =SUMIFS('Public Inputs'!$K$28:$K$147,'Public Inputs'!$A$28:$A$147,$C$3,'Public Inputs'!$B$28:$B$147,$A30,'Public Inputs'!$C$28:$C$147,$B30,'Public Inputs'!$D$28:$D$147,H$21) -> 2 | I30: =SUMIFS('Public Inputs'!$K$28:$K$147,'Public Inputs'!$A$28:$A$147,$C$3,'Public Inputs'!$B$28:$B$147,$A30,'Public Inputs'!$C$28:$C$147,$B30,'Public Inputs'!$D$28:$D$147,I$21) -> 5 | J30: Asset control, dependence on others, collective decisions | L30: =IFERROR(CHOOSE(MATCH($C$3,{"Schouwen-Duiveland","Walcheren","West-Zeeuws-Vlaanderen"},0),"GTO +0.5 — existing cooperation lowers the dependency objection.","","GTO −0.5 — chain parks decide centrally; a collective adds dependency."),"")
A31: Company | B31: Sustainability, image and strategic risk | D31: =INDEX('Public Inputs'!$C$6:$C$15,MATCH($B31,'Public Inputs'!$B$6:$B$15,0)) -> 0.15 | E31: =INDEX('Public Inputs'!$D$6:$D$15,MATCH($B31,'Public Inputs'!$B$6:$B$15,0)) -> Climate and energy impacts | F31: =SUMIFS('Public Inputs'!$K$28:$K$147,'Public Inputs'!$A$28:$A$147,$C$3,'Public Inputs'!$B$28:$B$147,$A31,'Public Inputs'!$C$28:$C$147,$B31,'Public Inputs'!$D$28:$D$147,F$21) -> 3 | G31: =SUMIFS('Public Inputs'!$K$28:$K$147,'Public Inputs'!$A$28:$A$147,$C$3,'Public Inputs'!$B$28:$B$147,$A31,'Public Inputs'!$C$28:$C$147,$B31,'Public Inputs'!$D$28:$D$147,G$21) -> 4 | H31: =SUMIFS('Public Inputs'!$K$28:$K$147,'Public Inputs'!$A$28:$A$147,$C$3,'Public Inputs'!$B$28:$B$147,$A31,'Public Inputs'!$C$28:$C$147,$B31,'Public Inputs'!$D$28:$D$147,H$21) -> 5 | I31: =SUMIFS('Public Inputs'!$K$28:$K$147,'Public Inputs'!$A$28:$A$147,$C$3,'Public Inputs'!$B$28:$B$147,$A31,'Public Inputs'!$C$28:$C$147,$B31,'Public Inputs'!$D$28:$D$147,I$21) -> 1 | J31: Electrification, PV and storage use, policy and strategy fit | L31: =IFERROR(CHOOSE(MATCH($C$3,{"Schouwen-Duiveland","Walcheren","West-Zeeuws-Vlaanderen"},0),"","",""),"")
A33: Interpretation and public-use note
A34: Response option is the umbrella term for the four alternatives. Battery + EMS and the Group Transport Agreement are the flexibility-solution subset; conventional grid reinforcement and no additional intervention are not flexibility solutions.
A35: Flexibility is assessed as a possible complement to or bridge towards reinforcement. It is not assumed to replace reinforcement where the percentage-based grid evidence indicates that physical capacity remains necessary.
A36: Score precision: every score is displayed to one decimal place (for example 3.7 / 5, not 4) and the same precision applies to all three cases. The underlying values are the full weighted results and are not rounded before display.
A37: Village demand indicators are public tourism-demand data and are shown in full. Confidentiality applies only to identifiers and absolute grid values: the workbook contains no village names, station names or codes, no absolute station load, capacity or relief values, no exact project costs or dates, no internal source filenames, no hidden sheets and no external links.

Sheet Public Inputs
A1: Public TAPIR Inputs and Scoring Logic
A2: Public version: village demand indicators are shown in full; village names, station names and all absolute grid load/capacity values are removed
A4: Editable base criteria, weights and response-option scores | N4: Case-specific pathway result library
A5: Actor | B5: Criterion | C5: Weight | D5: TAPIR factor | E5: KPI / evidence basis | F5: Conventional grid reinforcement | G5: Battery + EMS | H5: Group Transport Agreement | I5: No additional intervention | N5: Case region | O5: Response option | P5: Grid-operator score | Q5: Company score | R5: Equal actor average | S5: Result | T5: Lookup key
A6: Grid operator | B6: Grid-operator life-cycle cost and investment effect | C6: 0.3 | D6: Economic prospects | E6: Relative investment implications, flexibility cost and potential reinforcement deferral; absolute project values are excluded. | F6: 2 | G6: 4 | H6: 4 | I6: 5 | N6: Schouwen-Duiveland | O6: Conventional grid reinforcement | P6: =SUMIFS($L$28:$L$147,$A$28:$A$147,$N6,$B$28:$B$147,"Grid operator",$D$28:$D$147,$O6)/SUMIFS($J$28:$J$147,$A$28:$A$147,$N6,$B$28:$B$147,"Grid operator",$D$28:$D$147,$O6) -> 2.85 | Q6: =SUMIFS($L$28:$L$147,$A$28:$A$147,$N6,$B$28:$B$147,"Company",$D$28:$D$147,$O6)/SUMIFS($J$28:$J$147,$A$28:$A$147,$N6,$B$28:$B$147,"Company",$D$28:$D$147,$O6) -> 2.5 | R6: =(P6+Q6)/2 -> 2.675 | S6: =IF(R6=MAX(INDEX($R$6:$R$17,MATCH(N6,$N$6:$N$17,0)):INDEX($R$6:$R$17,MATCH(N6,$N$6:$N$17,0)+3)),"Preferred response option","-") -> - | T6: Schouwen-Duiveland|Conventional grid reinforcement
A7: Grid operator | B7: Timing, duration, reliability and predictability | C7: 0.2 | D7: Maturity | E7: Threshold exceedance pattern, timing, availability and asset life, expressed without absolute load data. | F7: 4 | G7: 2 | H7: 3 | I7: 1 | N7: Schouwen-Duiveland | O7: Battery + EMS | P7: =SUMIFS($L$28:$L$147,$A$28:$A$147,$N7,$B$28:$B$147,"Grid operator",$D$28:$D$147,$O7)/SUMIFS($J$28:$J$147,$A$28:$A$147,$N7,$B$28:$B$147,"Grid operator",$D$28:$D$147,$O7) -> 3.65 | Q7: =SUMIFS($L$28:$L$147,$A$28:$A$147,$N7,$B$28:$B$147,"Company",$D$28:$D$147,$O7)/SUMIFS($J$28:$J$147,$A$28:$A$147,$N7,$B$28:$B$147,"Company",$D$28:$D$147,$O7) -> 4.25 | R7: =(P7+Q7)/2 -> 3.95 | S7: =IF(R7=MAX(INDEX($R$6:$R$17,MATCH(N7,$N$6:$N$17,0)):INDEX($R$6:$R$17,MATCH(N7,$N$6:$N$17,0)+3)),"Preferred response option","-") -> Preferred response option | T7: Schouwen-Duiveland|Battery + EMS
A8: Grid operator | B8: Speed and effect on reinforcement bridge gap | C8: 0.2 | D8: Feasibility | E8: Whether an option is available during the bridge period and reduces ATC stress to 90% or below. | F8: 1 | G8: 5 | H8: 3 | I8: 2 | N8: Schouwen-Duiveland | O8: Group Transport Agreement | P8: =SUMIFS($L$28:$L$147,$A$28:$A$147,$N8,$B$28:$B$147,"Grid operator",$D$28:$D$147,$O8)/SUMIFS($J$28:$J$147,$A$28:$A$147,$N8,$B$28:$B$147,"Grid operator",$D$28:$D$147,$O8) -> 3.075 | Q8: =SUMIFS($L$28:$L$147,$A$28:$A$147,$N8,$B$28:$B$147,"Company",$D$28:$D$147,$O8)/SUMIFS($J$28:$J$147,$A$28:$A$147,$N8,$B$28:$B$147,"Company",$D$28:$D$147,$O8) -> 3.425 | R8: =(P8+Q8)/2 -> 3.25 | S8: =IF(R8=MAX(INDEX($R$6:$R$17,MATCH(N8,$N$6:$N$17,0)):INDEX($R$6:$R$17,MATCH(N8,$N$6:$N$17,0)+3)),"Preferred response option","-") -> - | T8: Schouwen-Duiveland|Group Transport Agreement
A9: Grid operator | B9: Technical and operational readiness | C9: 0.15 | D9: Maturity | E9: Installed assets, control systems and the operational status of flexibility arrangements. | F9: 5 | G9: 4 | H9: 2 | I9: 2 | N9: Schouwen-Duiveland | O9: No additional intervention | P9: =SUMIFS($L$28:$L$147,$A$28:$A$147,$N9,$B$28:$B$147,"Grid operator",$D$28:$D$147,$O9)/SUMIFS($J$28:$J$147,$A$28:$A$147,$N9,$B$28:$B$147,"Grid operator",$D$28:$D$147,$O9) -> 3.05 | Q9: =SUMIFS($L$28:$L$147,$A$28:$A$147,$N9,$B$28:$B$147,"Company",$D$28:$D$147,$O9)/SUMIFS($J$28:$J$147,$A$28:$A$147,$N9,$B$28:$B$147,"Company",$D$28:$D$147,$O9) -> 2.7 | R9: =(P9+Q9)/2 -> 2.875 | S9: =IF(R9=MAX(INDEX($R$6:$R$17,MATCH(N9,$N$6:$N$17,0)):INDEX($R$6:$R$17,MATCH(N9,$N$6:$N$17,0)+3)),"Preferred response option","-") -> - | T9: Schouwen-Duiveland|No additional intervention
A10: Grid operator | B10: Legal, contractual and policy embeddedness | C10: 0.15 | D10: Local embeddedness | E10: Legal status, agreements, connection conditions and policy alignment. | F10: 4 | G10: 3 | H10: 2 | I10: 5 | N10: Walcheren | O10: Conventional grid reinforcement | P10: =SUMIFS($L$28:$L$147,$A$28:$A$147,$N10,$B$28:$B$147,"Grid operator",$D$28:$D$147,$O10)/SUMIFS($J$28:$J$147,$A$28:$A$147,$N10,$B$28:$B$147,"Grid operator",$D$28:$D$147,$O10) -> 2.85 | Q10: =SUMIFS($L$28:$L$147,$A$28:$A$147,$N10,$B$28:$B$147,"Company",$D$28:$D$147,$O10)/SUMIFS($J$28:$J$147,$A$28:$A$147,$N10,$B$28:$B$147,"Company",$D$28:$D$147,$O10) -> 2.5 | R10: =(P10+Q10)/2 -> 2.675 | S10: =IF(R10=MAX(INDEX($R$6:$R$17,MATCH(N10,$N$6:$N$17,0)):INDEX($R$6:$R$17,MATCH(N10,$N$6:$N$17,0)+3)),"Preferred response option","-") -> - | T10: Walcheren|Conventional grid reinforcement
A11: Company | B11: Financial attractiveness | C11: 0.3 | D11: Economic prospects | E11: Relative cost, benefit, payback and compensation considerations; confidential monetary values are excluded. | F11: 2 | G11: 5 | H11: 4 | I11: 2 | N11: Walcheren | O11: Battery + EMS | P11: =SUMIFS($L$28:$L$147,$A$28:$A$147,$N11,$B$28:$B$147,"Grid operator",$D$28:$D$147,$O11)/SUMIFS($J$28:$J$147,$A$28:$A$147,$N11,$B$28:$B$147,"Grid operator",$D$28:$D$147,$O11) -> 3.975 | Q11: =SUMIFS($L$28:$L$147,$A$28:$A$147,$N11,$B$28:$B$147,"Company",$D$28:$D$147,$O11)/SUMIFS($J$28:$J$147,$A$28:$A$147,$N11,$B$28:$B$147,"Company",$D$28:$D$147,$O11) -> 4.45 | R11: =(P11+Q11)/2 -> 4.2125 | S11: =IF(R11=MAX(INDEX($R$6:$R$17,MATCH(N11,$N$6:$N$17,0)):INDEX($R$6:$R$17,MATCH(N11,$N$6:$N$17,0)+3)),"Preferred response option","-") -> Preferred response option | T11: Walcheren|Battery + EMS
A12: Company | B12: Implementation speed and urgency fit | C12: 0.2 | D12: Feasibility | E12: Case-specific lead time and availability before the constraint becomes binding. | F12: 1 | G12: 4 | H12: 3 | I12: 1 | N12: Walcheren | O12: Group Transport Agreement | P12: =SUMIFS($L$28:$L$147,$A$28:$A$147,$N12,$B$28:$B$147,"Grid operator",$D$28:$D$147,$O12)/SUMIFS($J$28:$J$147,$A$28:$A$147,$N12,$B$28:$B$147,"Grid operator",$D$28:$D$147,$O12) -> 3.05 | Q12: =SUMIFS($L$28:$L$147,$A$28:$A$147,$N12,$B$28:$B$147,"Company",$D$28:$D$147,$O12)/SUMIFS($J$28:$J$147,$A$28:$A$147,$N12,$B$28:$B$147,"Company",$D$28:$D$147,$O12) -> 3.3 | R12: =(P12+Q12)/2 -> 3.175 | S12: =IF(R12=MAX(INDEX($R$6:$R$17,MATCH(N12,$N$6:$N$17,0)):INDEX($R$6:$R$17,MATCH(N12,$N$6:$N$17,0)+3)),"Preferred response option","-") -> - | T12: Walcheren|Group Transport Agreement
A13: Company | B13: Knowledge and organisational burden | C13: 0.2 | D13: Scalability + feasibility | E13: Advice needs, actors involved, management time and coordination requirements. | F13: 4 | G13: 3 | H13: 2 | I13: 5 | N13: Walcheren | O13: No additional intervention | P13: =SUMIFS($L$28:$L$147,$A$28:$A$147,$N13,$B$28:$B$147,"Grid operator",$D$28:$D$147,$O13)/SUMIFS($J$28:$J$147,$A$28:$A$147,$N13,$B$28:$B$147,"Grid operator",$D$28:$D$147,$O13) -> 3.05 | Q13: =SUMIFS($L$28:$L$147,$A$28:$A$147,$N13,$B$28:$B$147,"Company",$D$28:$D$147,$O13)/SUMIFS($J$28:$J$147,$A$28:$A$147,$N13,$B$28:$B$147,"Company",$D$28:$D$147,$O13) -> 2.7 | R13: =(P13+Q13)/2 -> 2.875 | S13: =IF(R13=MAX(INDEX($R$6:$R$17,MATCH(N13,$N$6:$N$17,0)):INDEX($R$6:$R$17,MATCH(N13,$N$6:$N$17,0)+3)),"Preferred response option","-") -> - | T13: Walcheren|No additional intervention
A14: Company | B14: Autonomy and dependency | C14: 0.15 | D14: Regional relatedness + local embeddedness | E14: Asset control, dependence on other actors and collective decision requirements. | F14: 3 | G14: 5 | H14: 2 | I14: 5 | N14: West-Zeeuws-Vlaanderen | O14: Conventional grid reinforcement | P14: =SUMIFS($L$28:$L$147,$A$28:$A$147,$N14,$B$28:$B$147,"Grid operator",$D$28:$D$147,$O14)/SUMIFS($J$28:$J$147,$A$28:$A$147,$N14,$B$28:$B$147,"Grid operator",$D$28:$D$147,$O14) -> 2.85 | Q14: =SUMIFS($L$28:$L$147,$A$28:$A$147,$N14,$B$28:$B$147,"Company",$D$28:$D$147,$O14)/SUMIFS($J$28:$J$147,$A$28:$A$147,$N14,$B$28:$B$147,"Company",$D$28:$D$147,$O14) -> 2.5 | R14: =(P14+Q14)/2 -> 2.675 | S14: =IF(R14=MAX(INDEX($R$6:$R$17,MATCH(N14,$N$6:$N$17,0)):INDEX($R$6:$R$17,MATCH(N14,$N$6:$N$17,0)+3)),"Preferred response option","-") -> - | T14: West-Zeeuws-Vlaanderen|Conventional grid reinforcement
A15: Company | B15: Sustainability, image and strategic risk | C15: 0.15 | D15: Climate and energy impacts | E15: Electrification, renewable-energy use, policy alignment and strategic fit. | F15: 3 | G15: 4 | H15: 5 | I15: 1 | N15: West-Zeeuws-Vlaanderen | O15: Battery + EMS | P15: =SUMIFS($L$28:$L$147,$A$28:$A$147,$N15,$B$28:$B$147,"Grid operator",$D$28:$D$147,$O15)/SUMIFS($J$28:$J$147,$A$28:$A$147,$N15,$B$28:$B$147,"Grid operator",$D$28:$D$147,$O15) -> 3.8 | Q15: =SUMIFS($L$28:$L$147,$A$28:$A$147,$N15,$B$28:$B$147,"Company",$D$28:$D$147,$O15)/SUMIFS($J$28:$J$147,$A$28:$A$147,$N15,$B$28:$B$147,"Company",$D$28:$D$147,$O15) -> 4.35 | R15: =(P15+Q15)/2 -> 4.075 | S15: =IF(R15=MAX(INDEX($R$6:$R$17,MATCH(N15,$N$6:$N$17,0)):INDEX($R$6:$R$17,MATCH(N15,$N$6:$N$17,0)+3)),"Preferred response option","-") -> Preferred response option | T15: West-Zeeuws-Vlaanderen|Battery + EMS
N16: West-Zeeuws-Vlaanderen | O16: Group Transport Agreement | P16: =SUMIFS($L$28:$L$147,$A$28:$A$147,$N16,$B$28:$B$147,"Grid operator",$D$28:$D$147,$O16)/SUMIFS($J$28:$J$147,$A$28:$A$147,$N16,$B$28:$B$147,"Grid operator",$D$28:$D$147,$O16) -> 2.975 | Q16: =SUMIFS($L$28:$L$147,$A$28:$A$147,$N16,$B$28:$B$147,"Company",$D$28:$D$147,$O16)/SUMIFS($J$28:$J$147,$A$28:$A$147,$N16,$B$28:$B$147,"Company",$D$28:$D$147,$O16) -> 3.225 | R16: =(P16+Q16)/2 -> 3.1 | S16: =IF(R16=MAX(INDEX($R$6:$R$17,MATCH(N16,$N$6:$N$17,0)):INDEX($R$6:$R$17,MATCH(N16,$N$6:$N$17,0)+3)),"Preferred response option","-") -> - | T16: West-Zeeuws-Vlaanderen|Group Transport Agreement
A17: Weight validation | B17: Grid operator | C17: =SUMIF($A$6:$A$15,"Grid operator",$C$6:$C$15) -> 1 | D17: Company | E17: =SUMIF($A$6:$A$15,"Company",$C$6:$C$15) -> 1 | F17: =IF(AND(ABS(C17-1)<0.0001,ABS(E17-1)<0.0001),"OK — both actors total 100%","Review weights") -> OK — both actors total 100% | N17: West-Zeeuws-Vlaanderen | O17: No additional intervention | P17: =SUMIFS($L$28:$L$147,$A$28:$A$147,$N17,$B$28:$B$147,"Grid operator",$D$28:$D$147,$O17)/SUMIFS($J$28:$J$147,$A$28:$A$147,$N17,$B$28:$B$147,"Grid operator",$D$28:$D$147,$O17) -> 3.05 | Q17: =SUMIFS($L$28:$L$147,$A$28:$A$147,$N17,$B$28:$B$147,"Company",$D$28:$D$147,$O17)/SUMIFS($J$28:$J$147,$A$28:$A$147,$N17,$B$28:$B$147,"Company",$D$28:$D$147,$O17) -> 2.7 | R17: =(P17+Q17)/2 -> 2.875 | S17: =IF(R17=MAX(INDEX($R$6:$R$17,MATCH(N17,$N$6:$N$17,0)):INDEX($R$6:$R$17,MATCH(N17,$N$6:$N$17,0)+3)),"Preferred response option","-") -> - | T17: West-Zeeuws-Vlaanderen|No additional intervention
A20: Anonymised case indicators — load values expressed only as percentages | N20: Selected-case adjustment summaries | V20: Public village demand indicators and two-station percentage load indicators
A21: Case region | B21: Public village label | C21: Data coverage | E21: Distribution / MS-level station: peak as % of capacity | F21: High-voltage station: baseline peak as % of capacity | G21: High-voltage station: after battery + EMS | H21: High-voltage station: after Group Transport Agreement | I21: Evidence basis | J21: Threshold result | K21: Public grid summary | L21: Interview synthesis | M21: Public-data note | N21: Case region | O21: Criterion | P21: Public adjustment summary | Q21: Lookup key | V21: Village data coverage | W21: Village average daily demand (kWh/day) | X21: Village maximum peak (kW) | Y21: Peak period containing the annual maximum | Z21: Peak-period average daily demand (kWh/day) | AA21: MS ATC stress 2025 | AB21: MS ATC stress 2031 | AC21: MS first constraint year | AD21: MS critical hours at or above 90% | AE21: MS holiday share of critical hours | AF21: HVS ATC stress 2025 | AG21: HVS ATC stress 2031 | AH21: HVS first constraint year | AI21: HVS critical hours at or above 90% | AJ21: HVS holiday share of critical hours | AK21: Scenario and evidence-year note
A22: Schouwen-Duiveland | B22: Village 1 | C22: 1 | E22: 0.887 | F22: 0.97 | G22: 0.914 | H22: 0.916 | I22: Forecast percentage | J22: Neither flexibility solution clears the 90% threshold | K22: The high-voltage station is forecast to exceed the threshold before planned reinforcement. Both flexibility solutions reduce stress, but neither removes the exceedance; reinforcement therefore remains necessary. | L22: Interview synthesis indicates that existing regional cooperation may lower the coordination burden for a collective agreement, while companies continue to value autonomy and options that can be implemented quickly. | M22: All load and capacity indicators are normalised percentages. Absolute electrical values, station identifiers and exact project inputs have been removed. | N22: Schouwen-Duiveland | O22: Grid-operator life-cycle cost and investment effect | P22: Base score unchanged for this criterion. | Q22: Schouwen-Duiveland|Grid-operator life-cycle cost and investment effect | V22: 1 | W22: 43062 | X22: 5049.6 | Y22: Christmas holiday | Z22: 67345.2 | AA22: 0.666 | AB22: 0.887 | AC22: N/A | AD22: 0 total / 0 holiday | AE22: N/A | AF22: 0.762 | AG22: 0.97 | AH22: 2031 | AI22: 10 total / 7 holiday | AJ22: 0.7 | AK22: Both percentages are forecast values. The distribution-level percentage cannot be reproduced from the forecast series at the stated capacity, so its evidence year is unresolved; the high-voltage percentage is the 2031 forecast. Flexibility lowers the high-voltage level to 91.4% (battery + EMS) and 91.6% (Group Transport Agreement), so neither clears 90%.
A23: Walcheren | B23: Village 2 | C23: 1 | E23: 0.823 | F23: 0.948 | G23: 0.883 | H23: 0.891 | I23: Measured percentage test | J23: Both flexibility solutions clear the 90% threshold in the measured test | K23: Short peaks at the high-voltage station are reduced below the threshold by both flexibility solutions. The margins are narrow, and performance over the full period remains uncertain without a forward series. | L23: Interview synthesis indicates that battery and EMS operation is already established at several companies. Collective initiatives are less mature and place more coordination responsibility on participating companies. | M23: All load and capacity indicators are normalised percentages. Absolute electrical values, station identifiers and exact project inputs have been removed. | N23: Schouwen-Duiveland | O23: Timing, duration, reliability and predictability | P23: Reinforcement follows a short bridge period while the binding-component stress exceeds the 90% threshold. | Q23: Schouwen-Duiveland|Timing, duration, reliability and predictability | V23: 1 | W23: 29171.2 | X23: 3644.4 | Y23: Christmas holiday | Z23: 48505.2 | AA23: 0.634 | AB23: 0.823 | AC23: 2035 | AD23: 0 total / 0 holiday | AE23: N/A | AF23: 0.948 | AG23: >100% | AH23: 2025 | AI23: 4.25 total / 1.75 holiday | AJ23: 0.412 | AK23: The high-voltage percentage is a 2025 measurement; no forward forecast series exists for that level because reinforcement follows in the short term. The distribution-level percentage is the 2031 forecast. Flexibility lowers the high-voltage level to 88.3% (battery + EMS) and 89.1% (Group Transport Agreement).
A24: West-Zeeuws-Vlaanderen | B24: Village 3 | C24: 0.84109589 | E24: 0.539 | F24: 0.906 | G24: 0.861 | H24: 0.858 | I24: Measured percentage test | J24: Both flexibility solutions clear the 90% threshold initially; future coverage is uncertain | K24: The high-voltage station marginally exceeds the threshold in the measured profile. Both flexibility solutions clear the threshold initially, but the longer-term result and the link to reinforcement remain uncertain. | L24: Interview synthesis indicates that batteries are under consideration, whereas central company decision structures and limited collective governance increase the coordination burden for a Group Transport Agreement. | M24: All load and capacity indicators are normalised percentages. Absolute electrical values, station identifiers and exact project inputs have been removed. | N24: Schouwen-Duiveland | O24: Speed and effect on reinforcement bridge gap | P24: No relief is provided during the bridge period; the baseline ATC stress remains 97.0%. | Q24: Schouwen-Duiveland|Speed and effect on reinforcement bridge gap | V24: 1 | W24: 9414.6 | X24: 1450 | Y24: N/A - annual peak outside the defined periods | Z24: N/A | AA24: 0.43 | AB24: 0.539 | AC24: N/A | AD24: 0 total / 0 holiday | AE24: N/A | AF24: 0.906 | AG24: >100% | AH24: 2029 | AI24: 1 total / 0 holiday | AJ24: Not derived | AK24: The high-voltage percentage is a 2025 measurement; the holiday split of the single critical hour was not derived. The distribution-level percentage is the earliest available forecast year (2026) rather than 2031, and that level stays below capacity across the forecast horizon. Flexibility lowers the high-voltage level to 86.1% (battery + EMS) and 85.8% (Group Transport Agreement).
N25: Schouwen-Duiveland | O25: Technical and operational readiness | P25: Regional energy cooperation is developing, which improves the relative readiness of a collective arrangement. | Q25: Schouwen-Duiveland|Technical and operational readiness
A26: Case-specific regional adjustments and transparent score calculation | N26: Schouwen-Duiveland | O26: Legal, contractual and policy embeddedness | P26: Base score unchanged for this criterion. | Q26: Schouwen-Duiveland|Legal, contractual and policy embeddedness
A27: Case region | B27: Actor | C27: Criterion | D27: Response option | E27: Regional adjustment | F27: Public evidence | G27: Evidence type | H27: Calculation key | I27: Base score | J27: Weight | K27: Adjusted score | L27: Weighted contribution | N27: Schouwen-Duiveland | O27: Financial attractiveness | P27: Base score unchanged for this criterion. | Q27: Schouwen-Duiveland|Financial attractiveness
A28: Schouwen-Duiveland | B28: Grid operator | C28: Grid-operator life-cycle cost and investment effect | D28: Conventional grid reinforcement | E28: 0 | F28: Base score unchanged for this case. | G28: Base TAPIR assessment | H28: Schouwen-Duiveland|Grid operator|Grid-operator life-cycle cost and investment effect|Conventional grid reinforcement | I28: =INDEX($F$6:$I$15,MATCH($C28,$B$6:$B$15,0),MATCH($D28,$F$5:$I$5,0)) -> 2 | J28: =INDEX($C$6:$C$15,MATCH($C28,$B$6:$B$15,0)) -> 0.3 | K28: =MAX(1,MIN(5,I28+E28)) -> 2 | L28: =J28*K28 -> 0.6 | N28: Schouwen-Duiveland | O28: Implementation speed and urgency fit | P28: Base score unchanged for this criterion. | Q28: Schouwen-Duiveland|Implementation speed and urgency fit
A29: Schouwen-Duiveland | B29: Grid operator | C29: Grid-operator life-cycle cost and investment effect | D29: Battery + EMS | E29: 0 | F29: Base score unchanged for this case. | G29: Base TAPIR assessment | H29: Schouwen-Duiveland|Grid operator|Grid-operator life-cycle cost and investment effect|Battery + EMS | I29: =INDEX($F$6:$I$15,MATCH($C29,$B$6:$B$15,0),MATCH($D29,$F$5:$I$5,0)) -> 4 | J29: =INDEX($C$6:$C$15,MATCH($C29,$B$6:$B$15,0)) -> 0.3 | K29: =MAX(1,MIN(5,I29+E29)) -> 4 | L29: =J29*K29 -> 1.2 | N29: Schouwen-Duiveland | O29: Knowledge and organisational burden | P29: Regional groups and municipal facilitation can reduce the coordination burden. | Q29: Schouwen-Duiveland|Knowledge and organisational burden
A30: Schouwen-Duiveland | B30: Grid operator | C30: Grid-operator life-cycle cost and investment effect | D30: Group Transport Agreement | E30: 0 | F30: Base score unchanged for this case. | G30: Base TAPIR assessment | H30: Schouwen-Duiveland|Grid operator|Grid-operator life-cycle cost and investment effect|Group Transport Agreement | I30: =INDEX($F$6:$I$15,MATCH($C30,$B$6:$B$15,0),MATCH($D30,$F$5:$I$5,0)) -> 4 | J30: =INDEX($C$6:$C$15,MATCH($C30,$B$6:$B$15,0)) -> 0.3 | K30: =MAX(1,MIN(5,I30+E30)) -> 4 | L30: =J30*K30 -> 1.2 | N30: Schouwen-Duiveland | O30: Autonomy and dependency | P30: Existing cooperation reduces the dependency objection identified by participating companies. | Q30: Schouwen-Duiveland|Autonomy and dependency
A31: Schouwen-Duiveland | B31: Grid operator | C31: Grid-operator life-cycle cost and investment effect | D31: No additional intervention | E31: 0 | F31: Base score unchanged for this case. | G31: Base TAPIR assessment | H31: Schouwen-Duiveland|Grid operator|Grid-operator life-cycle cost and investment effect|No additional intervention | I31: =INDEX($F$6:$I$15,MATCH($C31,$B$6:$B$15,0),MATCH($D31,$F$5:$I$5,0)) -> 5 | J31: =INDEX($C$6:$C$15,MATCH($C31,$B$6:$B$15,0)) -> 0.3 | K31: =MAX(1,MIN(5,I31+E31)) -> 5 | L31: =J31*K31 -> 1.5 | N31: Schouwen-Duiveland | O31: Sustainability, image and strategic risk | P31: Base score unchanged for this criterion. | Q31: Schouwen-Duiveland|Sustainability, image and strategic risk
A32: Schouwen-Duiveland | B32: Grid operator | C32: Timing, duration, reliability and predictability | D32: Conventional grid reinforcement | E32: -0.5 | F32: Reinforcement follows a short bridge period while the binding-component stress exceeds the 90% threshold. | G32: Percentage-based grid assessment | H32: Schouwen-Duiveland|Grid operator|Timing, duration, reliability and predictability|Conventional grid reinforcement | I32: =INDEX($F$6:$I$15,MATCH($C32,$B$6:$B$15,0),MATCH($D32,$F$5:$I$5,0)) -> 4 | J32: =INDEX($C$6:$C$15,MATCH($C32,$B$6:$B$15,0)) -> 0.2 | K32: =MAX(1,MIN(5,I32+E32)) -> 3.5 | L32: =J32*K32 -> 0.7 | N32: Walcheren | O32: Grid-operator life-cycle cost and investment effect | P32: The measured ATC stress decreases from 94.8% to 88.3%, below the 90% threshold. | The measured ATC stress decreases from 94.8% to 89.1%, below the 90% threshold. | Q32: Walcheren|Grid-operator life-cycle cost and investment effect
A33: Schouwen-Duiveland | B33: Grid operator | C33: Timing, duration, reliability and predictability | D33: Battery + EMS | E33: 0 | F33: Base score unchanged for this case. | G33: Base TAPIR assessment | H33: Schouwen-Duiveland|Grid operator|Timing, duration, reliability and predictability|Battery + EMS | I33: =INDEX($F$6:$I$15,MATCH($C33,$B$6:$B$15,0),MATCH($D33,$F$5:$I$5,0)) -> 2 | J33: =INDEX($C$6:$C$15,MATCH($C33,$B$6:$B$15,0)) -> 0.2 | K33: =MAX(1,MIN(5,I33+E33)) -> 2 | L33: =J33*K33 -> 0.4 | N33: Walcheren | O33: Timing, duration, reliability and predictability | P33: The component is already constrained and reinforcement follows only after a bridge period. | The measured exceedance consists of short episodes, improving the fit of targeted storage dispatch. | Collective initiatives are at an early stage and are primarily focused on knowledge exchange. | Q33: Walcheren|Timing, duration, reliability and predictability
A34: Schouwen-Duiveland | B34: Grid operator | C34: Timing, duration, reliability and predictability | D34: Group Transport Agreement | E34: 0 | F34: Base score unchanged for this case. | G34: Base TAPIR assessment | H34: Schouwen-Duiveland|Grid operator|Timing, duration, reliability and predictability|Group Transport Agreement | I34: =INDEX($F$6:$I$15,MATCH($C34,$B$6:$B$15,0),MATCH($D34,$F$5:$I$5,0)) -> 3 | J34: =INDEX($C$6:$C$15,MATCH($C34,$B$6:$B$15,0)) -> 0.2 | K34: =MAX(1,MIN(5,I34+E34)) -> 3 | L34: =J34*K34 -> 0.6 | N34: Walcheren | O34: Speed and effect on reinforcement bridge gap | P34: The battery test clears the 90% threshold during the available bridge period. | No intervention leaves the measured ATC stress at 94.8% throughout the bridge period. | Q34: Walcheren|Speed and effect on reinforcement bridge gap
A35: Schouwen-Duiveland | B35: Grid operator | C35: Timing, duration, reliability and predictability | D35: No additional intervention | E35: 0 | F35: Base score unchanged for this case. | G35: Base TAPIR assessment | H35: Schouwen-Duiveland|Grid operator|Timing, duration, reliability and predictability|No additional intervention | I35: =INDEX($F$6:$I$15,MATCH($C35,$B$6:$B$15,0),MATCH($D35,$F$5:$I$5,0)) -> 1 | J35: =INDEX($C$6:$C$15,MATCH($C35,$B$6:$B$15,0)) -> 0.2 | K35: =MAX(1,MIN(5,I35+E35)) -> 1 | L35: =J35*K35 -> 0.2 | N35: Walcheren | O35: Technical and operational readiness | P35: Several companies already operate batteries with an Energy Management System. | Q35: Walcheren|Technical and operational readiness
A36: Schouwen-Duiveland | B36: Grid operator | C36: Speed and effect on reinforcement bridge gap | D36: Conventional grid reinforcement | E36: 0 | F36: Base score unchanged for this case. | G36: Base TAPIR assessment | H36: Schouwen-Duiveland|Grid operator|Speed and effect on reinforcement bridge gap|Conventional grid reinforcement | I36: =INDEX($F$6:$I$15,MATCH($C36,$B$6:$B$15,0),MATCH($D36,$F$5:$I$5,0)) -> 1 | J36: =INDEX($C$6:$C$15,MATCH($C36,$B$6:$B$15,0)) -> 0.2 | K36: =MAX(1,MIN(5,I36+E36)) -> 1 | L36: =J36*K36 -> 0.2 | N36: Walcheren | O36: Legal, contractual and policy embeddedness | P36: Base score unchanged for this criterion. | Q36: Walcheren|Legal, contractual and policy embeddedness
A37: Schouwen-Duiveland | B37: Grid operator | C37: Speed and effect on reinforcement bridge gap | D37: Battery + EMS | E37: 0 | F37: Base score unchanged for this case. | G37: Base TAPIR assessment | H37: Schouwen-Duiveland|Grid operator|Speed and effect on reinforcement bridge gap|Battery + EMS | I37: =INDEX($F$6:$I$15,MATCH($C37,$B$6:$B$15,0),MATCH($D37,$F$5:$I$5,0)) -> 5 | J37: =INDEX($C$6:$C$15,MATCH($C37,$B$6:$B$15,0)) -> 0.2 | K37: =MAX(1,MIN(5,I37+E37)) -> 5 | L37: =J37*K37 -> 1 | N37: Walcheren | O37: Financial attractiveness | P37: Companies view the option more favourably where it is cost-neutral and delivers usable connection capacity. | The arrangement can reduce stress without requiring company-owned grid infrastructure. | Q37: Walcheren|Financial attractiveness
A38: Schouwen-Duiveland | B38: Grid operator | C38: Speed and effect on reinforcement bridge gap | D38: Group Transport Agreement | E38: 0 | F38: Base score unchanged for this case. | G38: Base TAPIR assessment | H38: Schouwen-Duiveland|Grid operator|Speed and effect on reinforcement bridge gap|Group Transport Agreement | I38: =INDEX($F$6:$I$15,MATCH($C38,$B$6:$B$15,0),MATCH($D38,$F$5:$I$5,0)) -> 3 | J38: =INDEX($C$6:$C$15,MATCH($C38,$B$6:$B$15,0)) -> 0.2 | K38: =MAX(1,MIN(5,I38+E38)) -> 3 | L38: =J38*K38 -> 0.6 | N38: Walcheren | O38: Implementation speed and urgency fit | P38: The solution can be implemented within the bridge period. | Q38: Walcheren|Implementation speed and urgency fit
A39: Schouwen-Duiveland | B39: Grid operator | C39: Speed and effect on reinforcement bridge gap | D39: No additional intervention | E39: -0.5 | F39: No relief is provided during the bridge period; the baseline ATC stress remains 97.0%. | G39: Percentage-based grid assessment | H39: Schouwen-Duiveland|Grid operator|Speed and effect on reinforcement bridge gap|No additional intervention | I39: =INDEX($F$6:$I$15,MATCH($C39,$B$6:$B$15,0),MATCH($D39,$F$5:$I$5,0)) -> 2 | J39: =INDEX($C$6:$C$15,MATCH($C39,$B$6:$B$15,0)) -> 0.2 | K39: =MAX(1,MIN(5,I39+E39)) -> 1.5 | L39: =J39*K39 -> 0.3 | N39: Walcheren | O39: Knowledge and organisational burden | P39: Battery and EMS operation is already established locally. | Collective implementation is company-led, placing coordination work on participating companies. | Q39: Walcheren|Knowledge and organisational burden
... A51: Schouwen-Duiveland | B51: Company | C51: Financial attractiveness | D51: No additional intervention | E51: 0 | F51: Base score unchanged for this case. | G51: Base TAPIR assessment | H51: Schouwen-Duiveland|Company|Financial attractiveness|No additional intervention | I51: =INDEX($F$6:$I$15,MATCH($C51,$B$6:$B$15,0),MATCH($D51,$F$5:$I$5,0)) -> 2 | J51: =INDEX($C$6:$C$15,MATCH($C51,$B$6:$B$15,0)) -> 0.3 | K51: =MAX(1,MIN(5,I51+E51)) -> 2 | L51: =J51*K51 -> 0.6 | N51: West-Zeeuws-Vlaanderen | O51: Sustainability, image and strategic risk | P51: Base score unchanged for this criterion. | Q51: West-Zeeuws-Vlaanderen|Sustainability, image and strategic risk
A52: Schouwen-Duiveland | B52: Company | C52: Implementation speed and urgency fit | D52: Conventional grid reinforcement | E52: 0 | F52: Base score unchanged for this case. | G52: Base TAPIR assessment | H52: Schouwen-Duiveland|Company|Implementation speed and urgency fit|Conventional grid reinforcement | I52: =INDEX($F$6:$I$15,MATCH($C52,$B$6:$B$15,0),MATCH($D52,$F$5:$I$5,0)) -> 1 | J52: =INDEX($C$6:$C$15,MATCH($C52,$B$6:$B$15,0)) -> 0.2 | K52: =MAX(1,MIN(5,I52+E52)) -> 1 | L52: =J52*K52 -> 0.2
A53: Schouwen-Duiveland | B53: Company | C53: Implementation speed and urgency fit | D53: Battery + EMS | E53: 0 | F53: Base score unchanged for this case. | G53: Base TAPIR assessment | H53: Schouwen-Duiveland|Company|Implementation speed and urgency fit|Battery + EMS | I53: =INDEX($F$6:$I$15,MATCH($C53,$B$6:$B$15,0),MATCH($D53,$F$5:$I$5,0)) -> 4 | J53: =INDEX($C$6:$C$15,MATCH($C53,$B$6:$B$15,0)) -> 0.2 | K53: =MAX(1,MIN(5,I53+E53)) -> 4 | L53: =J53*K53 -> 0.8
A54: Schouwen-Duiveland | B54: Company | C54: Implementation speed and urgency fit | D54: Group Transport Agreement | E54: 0 | F54: Base score unchanged for this case. | G54: Base TAPIR assessment | H54: Schouwen-Duiveland|Company|Implementation speed and urgency fit|Group Transport Agreement | I54: =INDEX($F$6:$I$15,MATCH($C54,$B$6:$B$15,0),MATCH($D54,$F$5:$I$5,0)) -> 3 | J54: =INDEX($C$6:$C$15,MATCH($C54,$B$6:$B$15,0)) -> 0.2 | K54: =MAX(1,MIN(5,I54+E54)) -> 3 | L54: =J54*K54 -> 0.6 | N54: Scoring rules
...

Sheet Read Me
A1: Read Me — Public TAPIR Decision-Support Tool
A2: This clean public workbook preserves the decision-support logic while removing confidential grid-operator asset and load information.
A4: How to use
A5: 1. Open the Public Tool sheet and select one of the three case regions in the yellow case selector.
A6: 2. Review the four response-option scores (one decimal place in every case), the compact village and two-station context block, and the criterion-level evidence., the public village demand indicators, the percentage-only load indicators for the two station levels and the case-specific evidence.
A7: 3. If sensitivity testing is required, edit only the yellow weight, base-score and regional-adjustment cells on Public Inputs.
A9: Terminology used
A10: Response option is the umbrella term for the alternatives assessed by the tool: conventional grid reinforcement, battery + EMS, Group Transport Agreement and no additional intervention.
A11: Flexibility solutions are the response-option subset that uses demand, generation or storage flexibility within available grid capacity: battery + EMS and the Group Transport Agreement.
A12: Grid reinforcement is not a flexibility solution. No additional intervention is the reference response option.
A14: Public anonymisation applied
A15: The three village names have been replaced by the non-identifying labels Village 1, Village 2 and Village 3, but the measured village demand indicators themselves are public and are shown in full.
... A31: Source basis: thesis Chapters 5–8, thesis case documents and the interview evidence already used in the thesis. Public release prepared without absolute grid-operator load or asset data.
